[2024-01-01T12:00:35.367-0300] {scheduler_job_runner.py:781} ERROR - Executor reports task instance <TaskInstance: postgres_operator.get_data scheduled__2024-01-01T14:00:00+00:00 [queued]> finished (failed) although the task says it's queued. (Info: None) Was the task killed externally?
