[2023-12-31T09:36:43.398-0300] {processor.py:161} INFO - Started process (PID=31971) to work on /home/felipe/airflow/dags/04_time_delta.py
[2023-12-31T09:36:43.399-0300] {processor.py:830} INFO - Processing file /home/felipe/airflow/dags/04_time_delta.py for tasks to queue
[2023-12-31T09:36:43.400-0300] {logging_mixin.py:188} INFO - [2023-12-31T09:36:43.400-0300] {dagbag.py:538} INFO - Filling up the DagBag from /home/felipe/airflow/dags/04_time_delta.py
[2023-12-31T09:36:43.416-0300] {logging_mixin.py:188} INFO - [2023-12-31T09:36:43.409-0300] {dagbag.py:348} ERROR - Failed to import: /home/felipe/airflow/dags/04_time_delta.py
Traceback (most recent call last):
  File "/home/felipe/.local/lib/python3.10/site-packages/airflow/models/dagbag.py", line 344, in parse
    loader.exec_module(new_module)
  File "<frozen importlib._bootstrap_external>", line 883, in exec_module
  File "<frozen importlib._bootstrap>", line 241, in _call_with_frames_removed
  File "/home/felipe/airflow/dags/04_time_delta.py", line 4, in <module>
    import pandas as pd
ModuleNotFoundError: No module named 'pandas'
[2023-12-31T09:36:43.417-0300] {processor.py:842} WARNING - No viable dags retrieved from /home/felipe/airflow/dags/04_time_delta.py
[2023-12-31T09:36:43.488-0300] {processor.py:183} INFO - Processing /home/felipe/airflow/dags/04_time_delta.py took 0.099 seconds
[2023-12-31T09:38:35.059-0300] {processor.py:161} INFO - Started process (PID=32174) to work on /home/felipe/airflow/dags/04_time_delta.py
[2023-12-31T09:38:35.067-0300] {processor.py:830} INFO - Processing file /home/felipe/airflow/dags/04_time_delta.py for tasks to queue
[2023-12-31T09:38:35.070-0300] {logging_mixin.py:188} INFO - [2023-12-31T09:38:35.069-0300] {dagbag.py:538} INFO - Filling up the DagBag from /home/felipe/airflow/dags/04_time_delta.py
[2023-12-31T09:38:35.099-0300] {logging_mixin.py:188} INFO - [2023-12-31T09:38:35.090-0300] {dagbag.py:348} ERROR - Failed to import: /home/felipe/airflow/dags/04_time_delta.py
Traceback (most recent call last):
  File "/home/felipe/.local/lib/python3.10/site-packages/airflow/models/dagbag.py", line 344, in parse
    loader.exec_module(new_module)
  File "<frozen importlib._bootstrap_external>", line 883, in exec_module
  File "<frozen importlib._bootstrap>", line 241, in _call_with_frames_removed
  File "/home/felipe/airflow/dags/04_time_delta.py", line 4, in <module>
    import pandas as pd
ModuleNotFoundError: No module named 'pandas'
[2023-12-31T09:38:35.100-0300] {processor.py:842} WARNING - No viable dags retrieved from /home/felipe/airflow/dags/04_time_delta.py
[2023-12-31T09:38:35.249-0300] {processor.py:183} INFO - Processing /home/felipe/airflow/dags/04_time_delta.py took 0.209 seconds
[2023-12-31T09:52:04.118-0300] {processor.py:161} INFO - Started process (PID=32774) to work on /home/felipe/airflow/dags/04_time_delta.py
[2023-12-31T09:52:04.127-0300] {processor.py:830} INFO - Processing file /home/felipe/airflow/dags/04_time_delta.py for tasks to queue
[2023-12-31T09:52:04.130-0300] {logging_mixin.py:188} INFO - [2023-12-31T09:52:04.129-0300] {dagbag.py:538} INFO - Filling up the DagBag from /home/felipe/airflow/dags/04_time_delta.py
[2023-12-31T09:52:04.148-0300] {logging_mixin.py:188} INFO - [2023-12-31T09:52:04.147-0300] {dagbag.py:348} ERROR - Failed to import: /home/felipe/airflow/dags/04_time_delta.py
Traceback (most recent call last):
  File "/home/felipe/.local/lib/python3.10/site-packages/airflow/models/dagbag.py", line 344, in parse
    loader.exec_module(new_module)
  File "<frozen importlib._bootstrap_external>", line 883, in exec_module
  File "<frozen importlib._bootstrap>", line 241, in _call_with_frames_removed
  File "/home/felipe/airflow/dags/04_time_delta.py", line 4, in <module>
    import pandas as pd
ModuleNotFoundError: No module named 'pandas'
[2023-12-31T09:52:04.149-0300] {processor.py:842} WARNING - No viable dags retrieved from /home/felipe/airflow/dags/04_time_delta.py
[2023-12-31T09:52:04.317-0300] {processor.py:183} INFO - Processing /home/felipe/airflow/dags/04_time_delta.py took 0.219 seconds
[2023-12-31T09:55:22.600-0300] {processor.py:161} INFO - Started process (PID=32930) to work on /home/felipe/airflow/dags/04_time_delta.py
[2023-12-31T09:55:22.618-0300] {processor.py:830} INFO - Processing file /home/felipe/airflow/dags/04_time_delta.py for tasks to queue
[2023-12-31T09:55:22.640-0300] {logging_mixin.py:188} INFO - [2023-12-31T09:55:22.638-0300] {dagbag.py:538} INFO - Filling up the DagBag from /home/felipe/airflow/dags/04_time_delta.py
[2023-12-31T09:55:22.739-0300] {logging_mixin.py:188} INFO - [2023-12-31T09:55:22.710-0300] {dagbag.py:348} ERROR - Failed to import: /home/felipe/airflow/dags/04_time_delta.py
Traceback (most recent call last):
  File "/home/felipe/.local/lib/python3.10/site-packages/airflow/models/dagbag.py", line 344, in parse
    loader.exec_module(new_module)
  File "<frozen importlib._bootstrap_external>", line 883, in exec_module
  File "<frozen importlib._bootstrap>", line 241, in _call_with_frames_removed
  File "/home/felipe/airflow/dags/04_time_delta.py", line 4, in <module>
    import pandas as pd
ModuleNotFoundError: No module named 'pandas'
[2023-12-31T09:55:22.758-0300] {processor.py:842} WARNING - No viable dags retrieved from /home/felipe/airflow/dags/04_time_delta.py
[2023-12-31T09:55:23.067-0300] {processor.py:183} INFO - Processing /home/felipe/airflow/dags/04_time_delta.py took 0.507 seconds
[2023-12-31T09:59:58.099-0300] {processor.py:161} INFO - Started process (PID=33147) to work on /home/felipe/airflow/dags/04_time_delta.py
[2023-12-31T09:59:58.110-0300] {processor.py:830} INFO - Processing file /home/felipe/airflow/dags/04_time_delta.py for tasks to queue
[2023-12-31T09:59:58.119-0300] {logging_mixin.py:188} INFO - [2023-12-31T09:59:58.118-0300] {dagbag.py:538} INFO - Filling up the DagBag from /home/felipe/airflow/dags/04_time_delta.py
[2023-12-31T09:59:58.138-0300] {logging_mixin.py:188} INFO - [2023-12-31T09:59:58.137-0300] {dagbag.py:348} ERROR - Failed to import: /home/felipe/airflow/dags/04_time_delta.py
Traceback (most recent call last):
  File "/home/felipe/.local/lib/python3.10/site-packages/airflow/models/dagbag.py", line 344, in parse
    loader.exec_module(new_module)
  File "<frozen importlib._bootstrap_external>", line 883, in exec_module
  File "<frozen importlib._bootstrap>", line 241, in _call_with_frames_removed
  File "/home/felipe/airflow/dags/04_time_delta.py", line 4, in <module>
    import pandas as pd
ModuleNotFoundError: No module named 'pandas'
[2023-12-31T09:59:58.139-0300] {processor.py:842} WARNING - No viable dags retrieved from /home/felipe/airflow/dags/04_time_delta.py
[2023-12-31T09:59:58.239-0300] {processor.py:183} INFO - Processing /home/felipe/airflow/dags/04_time_delta.py took 0.152 seconds
[2023-12-31T10:01:24.716-0300] {processor.py:161} INFO - Started process (PID=33275) to work on /home/felipe/airflow/dags/04_time_delta.py
[2023-12-31T10:01:24.719-0300] {processor.py:830} INFO - Processing file /home/felipe/airflow/dags/04_time_delta.py for tasks to queue
[2023-12-31T10:01:24.727-0300] {logging_mixin.py:188} INFO - [2023-12-31T10:01:24.720-0300] {dagbag.py:538} INFO - Filling up the DagBag from /home/felipe/airflow/dags/04_time_delta.py
[2023-12-31T10:01:24.738-0300] {logging_mixin.py:188} INFO - [2023-12-31T10:01:24.737-0300] {dagbag.py:348} ERROR - Failed to import: /home/felipe/airflow/dags/04_time_delta.py
Traceback (most recent call last):
  File "/home/felipe/.local/lib/python3.10/site-packages/airflow/models/dagbag.py", line 344, in parse
    loader.exec_module(new_module)
  File "<frozen importlib._bootstrap_external>", line 883, in exec_module
  File "<frozen importlib._bootstrap>", line 241, in _call_with_frames_removed
  File "/home/felipe/airflow/dags/04_time_delta.py", line 4, in <module>
    import pandas as pd
ModuleNotFoundError: No module named 'pandas'
[2023-12-31T10:01:24.739-0300] {processor.py:842} WARNING - No viable dags retrieved from /home/felipe/airflow/dags/04_time_delta.py
[2023-12-31T10:01:24.906-0300] {processor.py:183} INFO - Processing /home/felipe/airflow/dags/04_time_delta.py took 0.207 seconds
[2023-12-31T10:02:33.458-0300] {processor.py:161} INFO - Started process (PID=33342) to work on /home/felipe/airflow/dags/04_time_delta.py
[2023-12-31T10:02:33.466-0300] {processor.py:830} INFO - Processing file /home/felipe/airflow/dags/04_time_delta.py for tasks to queue
[2023-12-31T10:02:33.468-0300] {logging_mixin.py:188} INFO - [2023-12-31T10:02:33.467-0300] {dagbag.py:538} INFO - Filling up the DagBag from /home/felipe/airflow/dags/04_time_delta.py
[2023-12-31T10:02:33.487-0300] {logging_mixin.py:188} INFO - [2023-12-31T10:02:33.479-0300] {dagbag.py:348} ERROR - Failed to import: /home/felipe/airflow/dags/04_time_delta.py
Traceback (most recent call last):
  File "/home/felipe/.local/lib/python3.10/site-packages/airflow/models/dagbag.py", line 344, in parse
    loader.exec_module(new_module)
  File "<frozen importlib._bootstrap_external>", line 883, in exec_module
  File "<frozen importlib._bootstrap>", line 241, in _call_with_frames_removed
  File "/home/felipe/airflow/dags/04_time_delta.py", line 4, in <module>
    import pandas as pd
ModuleNotFoundError: No module named 'pandas'
[2023-12-31T10:02:33.488-0300] {processor.py:842} WARNING - No viable dags retrieved from /home/felipe/airflow/dags/04_time_delta.py
[2023-12-31T10:02:33.587-0300] {processor.py:183} INFO - Processing /home/felipe/airflow/dags/04_time_delta.py took 0.140 seconds
[2023-12-31T10:03:38.408-0300] {processor.py:161} INFO - Started process (PID=33414) to work on /home/felipe/airflow/dags/04_time_delta.py
[2023-12-31T10:03:38.417-0300] {processor.py:830} INFO - Processing file /home/felipe/airflow/dags/04_time_delta.py for tasks to queue
[2023-12-31T10:03:38.418-0300] {logging_mixin.py:188} INFO - [2023-12-31T10:03:38.418-0300] {dagbag.py:538} INFO - Filling up the DagBag from /home/felipe/airflow/dags/04_time_delta.py
[2023-12-31T10:03:38.430-0300] {logging_mixin.py:188} INFO - [2023-12-31T10:03:38.428-0300] {dagbag.py:348} ERROR - Failed to import: /home/felipe/airflow/dags/04_time_delta.py
Traceback (most recent call last):
  File "/home/felipe/.local/lib/python3.10/site-packages/airflow/models/dagbag.py", line 344, in parse
    loader.exec_module(new_module)
  File "<frozen importlib._bootstrap_external>", line 883, in exec_module
  File "<frozen importlib._bootstrap>", line 241, in _call_with_frames_removed
  File "/home/felipe/airflow/dags/04_time_delta.py", line 4, in <module>
    import pandas as pd
ModuleNotFoundError: No module named 'pandas'
[2023-12-31T10:03:38.437-0300] {processor.py:842} WARNING - No viable dags retrieved from /home/felipe/airflow/dags/04_time_delta.py
[2023-12-31T10:03:38.530-0300] {processor.py:183} INFO - Processing /home/felipe/airflow/dags/04_time_delta.py took 0.133 seconds
[2023-12-31T10:04:50.349-0300] {processor.py:161} INFO - Started process (PID=33497) to work on /home/felipe/airflow/dags/04_time_delta.py
[2023-12-31T10:04:50.358-0300] {processor.py:830} INFO - Processing file /home/felipe/airflow/dags/04_time_delta.py for tasks to queue
[2023-12-31T10:04:50.377-0300] {logging_mixin.py:188} INFO - [2023-12-31T10:04:50.376-0300] {dagbag.py:538} INFO - Filling up the DagBag from /home/felipe/airflow/dags/04_time_delta.py
[2023-12-31T10:04:50.409-0300] {logging_mixin.py:188} INFO - [2023-12-31T10:04:50.398-0300] {dagbag.py:348} ERROR - Failed to import: /home/felipe/airflow/dags/04_time_delta.py
Traceback (most recent call last):
  File "/home/felipe/.local/lib/python3.10/site-packages/airflow/models/dagbag.py", line 344, in parse
    loader.exec_module(new_module)
  File "<frozen importlib._bootstrap_external>", line 883, in exec_module
  File "<frozen importlib._bootstrap>", line 241, in _call_with_frames_removed
  File "/home/felipe/airflow/dags/04_time_delta.py", line 4, in <module>
    import pandas as pd
ModuleNotFoundError: No module named 'pandas'
[2023-12-31T10:04:50.419-0300] {processor.py:842} WARNING - No viable dags retrieved from /home/felipe/airflow/dags/04_time_delta.py
[2023-12-31T10:04:50.526-0300] {processor.py:183} INFO - Processing /home/felipe/airflow/dags/04_time_delta.py took 0.190 seconds
[2023-12-31T10:06:01.628-0300] {processor.py:161} INFO - Started process (PID=33580) to work on /home/felipe/airflow/dags/04_time_delta.py
[2023-12-31T10:06:01.637-0300] {processor.py:830} INFO - Processing file /home/felipe/airflow/dags/04_time_delta.py for tasks to queue
[2023-12-31T10:06:01.638-0300] {logging_mixin.py:188} INFO - [2023-12-31T10:06:01.638-0300] {dagbag.py:538} INFO - Filling up the DagBag from /home/felipe/airflow/dags/04_time_delta.py
[2023-12-31T10:06:01.657-0300] {logging_mixin.py:188} INFO - [2023-12-31T10:06:01.649-0300] {dagbag.py:348} ERROR - Failed to import: /home/felipe/airflow/dags/04_time_delta.py
Traceback (most recent call last):
  File "/home/felipe/.local/lib/python3.10/site-packages/airflow/models/dagbag.py", line 344, in parse
    loader.exec_module(new_module)
  File "<frozen importlib._bootstrap_external>", line 883, in exec_module
  File "<frozen importlib._bootstrap>", line 241, in _call_with_frames_removed
  File "/home/felipe/airflow/dags/04_time_delta.py", line 4, in <module>
    import pandas as pd
ModuleNotFoundError: No module named 'pandas'
[2023-12-31T10:06:01.658-0300] {processor.py:842} WARNING - No viable dags retrieved from /home/felipe/airflow/dags/04_time_delta.py
[2023-12-31T10:06:01.779-0300] {processor.py:183} INFO - Processing /home/felipe/airflow/dags/04_time_delta.py took 0.161 seconds
[2023-12-31T10:07:11.999-0300] {processor.py:161} INFO - Started process (PID=33689) to work on /home/felipe/airflow/dags/04_time_delta.py
[2023-12-31T10:07:12.008-0300] {processor.py:830} INFO - Processing file /home/felipe/airflow/dags/04_time_delta.py for tasks to queue
[2023-12-31T10:07:12.009-0300] {logging_mixin.py:188} INFO - [2023-12-31T10:07:12.009-0300] {dagbag.py:538} INFO - Filling up the DagBag from /home/felipe/airflow/dags/04_time_delta.py
[2023-12-31T10:07:12.029-0300] {logging_mixin.py:188} INFO - [2023-12-31T10:07:12.027-0300] {dagbag.py:348} ERROR - Failed to import: /home/felipe/airflow/dags/04_time_delta.py
Traceback (most recent call last):
  File "/home/felipe/.local/lib/python3.10/site-packages/airflow/models/dagbag.py", line 344, in parse
    loader.exec_module(new_module)
  File "<frozen importlib._bootstrap_external>", line 883, in exec_module
  File "<frozen importlib._bootstrap>", line 241, in _call_with_frames_removed
  File "/home/felipe/airflow/dags/04_time_delta.py", line 4, in <module>
    import pandas as pd
ModuleNotFoundError: No module named 'pandas'
[2023-12-31T10:07:12.030-0300] {processor.py:842} WARNING - No viable dags retrieved from /home/felipe/airflow/dags/04_time_delta.py
[2023-12-31T10:07:12.137-0300] {processor.py:183} INFO - Processing /home/felipe/airflow/dags/04_time_delta.py took 0.149 seconds
[2023-12-31T10:08:25.328-0300] {processor.py:161} INFO - Started process (PID=33773) to work on /home/felipe/airflow/dags/04_time_delta.py
[2023-12-31T10:08:25.337-0300] {processor.py:830} INFO - Processing file /home/felipe/airflow/dags/04_time_delta.py for tasks to queue
[2023-12-31T10:08:25.339-0300] {logging_mixin.py:188} INFO - [2023-12-31T10:08:25.339-0300] {dagbag.py:538} INFO - Filling up the DagBag from /home/felipe/airflow/dags/04_time_delta.py
[2023-12-31T10:08:25.358-0300] {logging_mixin.py:188} INFO - [2023-12-31T10:08:25.356-0300] {dagbag.py:348} ERROR - Failed to import: /home/felipe/airflow/dags/04_time_delta.py
Traceback (most recent call last):
  File "/home/felipe/.local/lib/python3.10/site-packages/airflow/models/dagbag.py", line 344, in parse
    loader.exec_module(new_module)
  File "<frozen importlib._bootstrap_external>", line 883, in exec_module
  File "<frozen importlib._bootstrap>", line 241, in _call_with_frames_removed
  File "/home/felipe/airflow/dags/04_time_delta.py", line 4, in <module>
    import pandas as pd
ModuleNotFoundError: No module named 'pandas'
[2023-12-31T10:08:25.359-0300] {processor.py:842} WARNING - No viable dags retrieved from /home/felipe/airflow/dags/04_time_delta.py
[2023-12-31T10:08:25.469-0300] {processor.py:183} INFO - Processing /home/felipe/airflow/dags/04_time_delta.py took 0.152 seconds
[2023-12-31T11:28:59.604-0300] {processor.py:161} INFO - Started process (PID=33962) to work on /home/felipe/airflow/dags/04_time_delta.py
[2023-12-31T11:28:59.614-0300] {processor.py:830} INFO - Processing file /home/felipe/airflow/dags/04_time_delta.py for tasks to queue
[2023-12-31T11:28:59.627-0300] {logging_mixin.py:188} INFO - [2023-12-31T11:28:59.625-0300] {dagbag.py:538} INFO - Filling up the DagBag from /home/felipe/airflow/dags/04_time_delta.py
[2023-12-31T11:28:59.676-0300] {logging_mixin.py:188} INFO - [2023-12-31T11:28:59.674-0300] {dagbag.py:348} ERROR - Failed to import: /home/felipe/airflow/dags/04_time_delta.py
Traceback (most recent call last):
  File "/home/felipe/.local/lib/python3.10/site-packages/airflow/models/dagbag.py", line 344, in parse
    loader.exec_module(new_module)
  File "<frozen importlib._bootstrap_external>", line 883, in exec_module
  File "<frozen importlib._bootstrap>", line 241, in _call_with_frames_removed
  File "/home/felipe/airflow/dags/04_time_delta.py", line 4, in <module>
    import pandas as pd
ModuleNotFoundError: No module named 'pandas'
[2023-12-31T11:28:59.684-0300] {processor.py:842} WARNING - No viable dags retrieved from /home/felipe/airflow/dags/04_time_delta.py
[2023-12-31T11:29:00.275-0300] {processor.py:183} INFO - Processing /home/felipe/airflow/dags/04_time_delta.py took 0.699 seconds
[2023-12-31T11:30:50.936-0300] {processor.py:161} INFO - Started process (PID=34236) to work on /home/felipe/airflow/dags/04_time_delta.py
[2023-12-31T11:30:50.946-0300] {processor.py:830} INFO - Processing file /home/felipe/airflow/dags/04_time_delta.py for tasks to queue
[2023-12-31T11:30:50.955-0300] {logging_mixin.py:188} INFO - [2023-12-31T11:30:50.954-0300] {dagbag.py:538} INFO - Filling up the DagBag from /home/felipe/airflow/dags/04_time_delta.py
[2023-12-31T11:30:50.977-0300] {logging_mixin.py:188} INFO - [2023-12-31T11:30:50.966-0300] {dagbag.py:348} ERROR - Failed to import: /home/felipe/airflow/dags/04_time_delta.py
Traceback (most recent call last):
  File "/home/felipe/.local/lib/python3.10/site-packages/airflow/models/dagbag.py", line 344, in parse
    loader.exec_module(new_module)
  File "<frozen importlib._bootstrap_external>", line 883, in exec_module
  File "<frozen importlib._bootstrap>", line 241, in _call_with_frames_removed
  File "/home/felipe/airflow/dags/04_time_delta.py", line 4, in <module>
    import pandas as pd
ModuleNotFoundError: No module named 'pandas'
[2023-12-31T11:30:50.984-0300] {processor.py:842} WARNING - No viable dags retrieved from /home/felipe/airflow/dags/04_time_delta.py
[2023-12-31T11:30:51.125-0300] {processor.py:183} INFO - Processing /home/felipe/airflow/dags/04_time_delta.py took 0.210 seconds
[2023-12-31T11:32:22.086-0300] {processor.py:161} INFO - Started process (PID=34343) to work on /home/felipe/airflow/dags/04_time_delta.py
[2023-12-31T11:32:22.095-0300] {processor.py:830} INFO - Processing file /home/felipe/airflow/dags/04_time_delta.py for tasks to queue
[2023-12-31T11:32:22.097-0300] {logging_mixin.py:188} INFO - [2023-12-31T11:32:22.096-0300] {dagbag.py:538} INFO - Filling up the DagBag from /home/felipe/airflow/dags/04_time_delta.py
[2023-12-31T11:32:22.124-0300] {logging_mixin.py:188} INFO - [2023-12-31T11:32:22.115-0300] {dagbag.py:348} ERROR - Failed to import: /home/felipe/airflow/dags/04_time_delta.py
Traceback (most recent call last):
  File "/home/felipe/.local/lib/python3.10/site-packages/airflow/models/dagbag.py", line 344, in parse
    loader.exec_module(new_module)
  File "<frozen importlib._bootstrap_external>", line 883, in exec_module
  File "<frozen importlib._bootstrap>", line 241, in _call_with_frames_removed
  File "/home/felipe/airflow/dags/04_time_delta.py", line 4, in <module>
    import pandas as pd
ModuleNotFoundError: No module named 'pandas'
[2023-12-31T11:32:22.125-0300] {processor.py:842} WARNING - No viable dags retrieved from /home/felipe/airflow/dags/04_time_delta.py
[2023-12-31T11:32:22.245-0300] {processor.py:183} INFO - Processing /home/felipe/airflow/dags/04_time_delta.py took 0.170 seconds
[2023-12-31T11:33:53.095-0300] {processor.py:161} INFO - Started process (PID=34445) to work on /home/felipe/airflow/dags/04_time_delta.py
[2023-12-31T11:33:53.104-0300] {processor.py:830} INFO - Processing file /home/felipe/airflow/dags/04_time_delta.py for tasks to queue
[2023-12-31T11:33:53.105-0300] {logging_mixin.py:188} INFO - [2023-12-31T11:33:53.105-0300] {dagbag.py:538} INFO - Filling up the DagBag from /home/felipe/airflow/dags/04_time_delta.py
[2023-12-31T11:33:53.126-0300] {logging_mixin.py:188} INFO - [2023-12-31T11:33:53.116-0300] {dagbag.py:348} ERROR - Failed to import: /home/felipe/airflow/dags/04_time_delta.py
Traceback (most recent call last):
  File "/home/felipe/.local/lib/python3.10/site-packages/airflow/models/dagbag.py", line 344, in parse
    loader.exec_module(new_module)
  File "<frozen importlib._bootstrap_external>", line 883, in exec_module
  File "<frozen importlib._bootstrap>", line 241, in _call_with_frames_removed
  File "/home/felipe/airflow/dags/04_time_delta.py", line 4, in <module>
    import pandas as pd
ModuleNotFoundError: No module named 'pandas'
[2023-12-31T11:33:53.134-0300] {processor.py:842} WARNING - No viable dags retrieved from /home/felipe/airflow/dags/04_time_delta.py
[2023-12-31T11:33:53.246-0300] {processor.py:183} INFO - Processing /home/felipe/airflow/dags/04_time_delta.py took 0.169 seconds
[2023-12-31T11:35:14.746-0300] {processor.py:161} INFO - Started process (PID=34563) to work on /home/felipe/airflow/dags/04_time_delta.py
[2023-12-31T11:35:14.755-0300] {processor.py:830} INFO - Processing file /home/felipe/airflow/dags/04_time_delta.py for tasks to queue
[2023-12-31T11:35:14.764-0300] {logging_mixin.py:188} INFO - [2023-12-31T11:35:14.756-0300] {dagbag.py:538} INFO - Filling up the DagBag from /home/felipe/airflow/dags/04_time_delta.py
[2023-12-31T11:35:14.794-0300] {logging_mixin.py:188} INFO - [2023-12-31T11:35:14.784-0300] {dagbag.py:348} ERROR - Failed to import: /home/felipe/airflow/dags/04_time_delta.py
Traceback (most recent call last):
  File "/home/felipe/.local/lib/python3.10/site-packages/airflow/models/dagbag.py", line 344, in parse
    loader.exec_module(new_module)
  File "<frozen importlib._bootstrap_external>", line 883, in exec_module
  File "<frozen importlib._bootstrap>", line 241, in _call_with_frames_removed
  File "/home/felipe/airflow/dags/04_time_delta.py", line 4, in <module>
    import pandas as pd
ModuleNotFoundError: No module named 'pandas'
[2023-12-31T11:35:14.796-0300] {processor.py:842} WARNING - No viable dags retrieved from /home/felipe/airflow/dags/04_time_delta.py
[2023-12-31T11:35:14.927-0300] {processor.py:183} INFO - Processing /home/felipe/airflow/dags/04_time_delta.py took 0.192 seconds
[2023-12-31T11:36:38.056-0300] {processor.py:161} INFO - Started process (PID=34652) to work on /home/felipe/airflow/dags/04_time_delta.py
[2023-12-31T11:36:38.064-0300] {processor.py:830} INFO - Processing file /home/felipe/airflow/dags/04_time_delta.py for tasks to queue
[2023-12-31T11:36:38.066-0300] {logging_mixin.py:188} INFO - [2023-12-31T11:36:38.065-0300] {dagbag.py:538} INFO - Filling up the DagBag from /home/felipe/airflow/dags/04_time_delta.py
[2023-12-31T11:36:38.086-0300] {logging_mixin.py:188} INFO - [2023-12-31T11:36:38.085-0300] {dagbag.py:348} ERROR - Failed to import: /home/felipe/airflow/dags/04_time_delta.py
Traceback (most recent call last):
  File "/home/felipe/.local/lib/python3.10/site-packages/airflow/models/dagbag.py", line 344, in parse
    loader.exec_module(new_module)
  File "<frozen importlib._bootstrap_external>", line 883, in exec_module
  File "<frozen importlib._bootstrap>", line 241, in _call_with_frames_removed
  File "/home/felipe/airflow/dags/04_time_delta.py", line 4, in <module>
    import pandas as pd
ModuleNotFoundError: No module named 'pandas'
[2023-12-31T11:36:38.094-0300] {processor.py:842} WARNING - No viable dags retrieved from /home/felipe/airflow/dags/04_time_delta.py
[2023-12-31T11:36:38.255-0300] {processor.py:183} INFO - Processing /home/felipe/airflow/dags/04_time_delta.py took 0.211 seconds
[2023-12-31T11:38:02.005-0300] {processor.py:161} INFO - Started process (PID=34745) to work on /home/felipe/airflow/dags/04_time_delta.py
[2023-12-31T11:38:02.014-0300] {processor.py:830} INFO - Processing file /home/felipe/airflow/dags/04_time_delta.py for tasks to queue
[2023-12-31T11:38:02.016-0300] {logging_mixin.py:188} INFO - [2023-12-31T11:38:02.015-0300] {dagbag.py:538} INFO - Filling up the DagBag from /home/felipe/airflow/dags/04_time_delta.py
[2023-12-31T11:38:02.036-0300] {logging_mixin.py:188} INFO - [2023-12-31T11:38:02.034-0300] {dagbag.py:348} ERROR - Failed to import: /home/felipe/airflow/dags/04_time_delta.py
Traceback (most recent call last):
  File "/home/felipe/.local/lib/python3.10/site-packages/airflow/models/dagbag.py", line 344, in parse
    loader.exec_module(new_module)
  File "<frozen importlib._bootstrap_external>", line 883, in exec_module
  File "<frozen importlib._bootstrap>", line 241, in _call_with_frames_removed
  File "/home/felipe/airflow/dags/04_time_delta.py", line 4, in <module>
    import pandas as pd
ModuleNotFoundError: No module named 'pandas'
[2023-12-31T11:38:02.044-0300] {processor.py:842} WARNING - No viable dags retrieved from /home/felipe/airflow/dags/04_time_delta.py
[2023-12-31T11:38:02.175-0300] {processor.py:183} INFO - Processing /home/felipe/airflow/dags/04_time_delta.py took 0.190 seconds
[2023-12-31T11:39:23.746-0300] {processor.py:161} INFO - Started process (PID=34834) to work on /home/felipe/airflow/dags/04_time_delta.py
[2023-12-31T11:39:23.756-0300] {processor.py:830} INFO - Processing file /home/felipe/airflow/dags/04_time_delta.py for tasks to queue
[2023-12-31T11:39:23.766-0300] {logging_mixin.py:188} INFO - [2023-12-31T11:39:23.765-0300] {dagbag.py:538} INFO - Filling up the DagBag from /home/felipe/airflow/dags/04_time_delta.py
[2023-12-31T11:39:23.806-0300] {logging_mixin.py:188} INFO - [2023-12-31T11:39:23.794-0300] {dagbag.py:348} ERROR - Failed to import: /home/felipe/airflow/dags/04_time_delta.py
Traceback (most recent call last):
  File "/home/felipe/.local/lib/python3.10/site-packages/airflow/models/dagbag.py", line 344, in parse
    loader.exec_module(new_module)
  File "<frozen importlib._bootstrap_external>", line 883, in exec_module
  File "<frozen importlib._bootstrap>", line 241, in _call_with_frames_removed
  File "/home/felipe/airflow/dags/04_time_delta.py", line 4, in <module>
    import pandas as pd
ModuleNotFoundError: No module named 'pandas'
[2023-12-31T11:39:23.815-0300] {processor.py:842} WARNING - No viable dags retrieved from /home/felipe/airflow/dags/04_time_delta.py
[2023-12-31T11:39:23.955-0300] {processor.py:183} INFO - Processing /home/felipe/airflow/dags/04_time_delta.py took 0.229 seconds
[2023-12-31T11:40:47.145-0300] {processor.py:161} INFO - Started process (PID=34950) to work on /home/felipe/airflow/dags/04_time_delta.py
[2023-12-31T11:40:47.154-0300] {processor.py:830} INFO - Processing file /home/felipe/airflow/dags/04_time_delta.py for tasks to queue
[2023-12-31T11:40:47.156-0300] {logging_mixin.py:188} INFO - [2023-12-31T11:40:47.155-0300] {dagbag.py:538} INFO - Filling up the DagBag from /home/felipe/airflow/dags/04_time_delta.py
[2023-12-31T11:40:47.184-0300] {logging_mixin.py:188} INFO - [2023-12-31T11:40:47.174-0300] {dagbag.py:348} ERROR - Failed to import: /home/felipe/airflow/dags/04_time_delta.py
Traceback (most recent call last):
  File "/home/felipe/.local/lib/python3.10/site-packages/airflow/models/dagbag.py", line 344, in parse
    loader.exec_module(new_module)
  File "<frozen importlib._bootstrap_external>", line 883, in exec_module
  File "<frozen importlib._bootstrap>", line 241, in _call_with_frames_removed
  File "/home/felipe/airflow/dags/04_time_delta.py", line 4, in <module>
    import pandas as pd
ModuleNotFoundError: No module named 'pandas'
[2023-12-31T11:40:47.184-0300] {processor.py:842} WARNING - No viable dags retrieved from /home/felipe/airflow/dags/04_time_delta.py
[2023-12-31T11:40:47.306-0300] {processor.py:183} INFO - Processing /home/felipe/airflow/dags/04_time_delta.py took 0.179 seconds
[2023-12-31T11:42:21.075-0300] {processor.py:161} INFO - Started process (PID=35056) to work on /home/felipe/airflow/dags/04_time_delta.py
[2023-12-31T11:42:21.086-0300] {processor.py:830} INFO - Processing file /home/felipe/airflow/dags/04_time_delta.py for tasks to queue
[2023-12-31T11:42:21.095-0300] {logging_mixin.py:188} INFO - [2023-12-31T11:42:21.094-0300] {dagbag.py:538} INFO - Filling up the DagBag from /home/felipe/airflow/dags/04_time_delta.py
[2023-12-31T11:42:21.126-0300] {logging_mixin.py:188} INFO - [2023-12-31T11:42:21.115-0300] {dagbag.py:348} ERROR - Failed to import: /home/felipe/airflow/dags/04_time_delta.py
Traceback (most recent call last):
  File "/home/felipe/.local/lib/python3.10/site-packages/airflow/models/dagbag.py", line 344, in parse
    loader.exec_module(new_module)
  File "<frozen importlib._bootstrap_external>", line 883, in exec_module
  File "<frozen importlib._bootstrap>", line 241, in _call_with_frames_removed
  File "/home/felipe/airflow/dags/04_time_delta.py", line 4, in <module>
    import pandas as pd
ModuleNotFoundError: No module named 'pandas'
[2023-12-31T11:42:21.135-0300] {processor.py:842} WARNING - No viable dags retrieved from /home/felipe/airflow/dags/04_time_delta.py
[2023-12-31T11:42:21.345-0300] {processor.py:183} INFO - Processing /home/felipe/airflow/dags/04_time_delta.py took 0.291 seconds
[2023-12-31T11:43:56.965-0300] {processor.py:161} INFO - Started process (PID=35166) to work on /home/felipe/airflow/dags/04_time_delta.py
[2023-12-31T11:43:56.974-0300] {processor.py:830} INFO - Processing file /home/felipe/airflow/dags/04_time_delta.py for tasks to queue
[2023-12-31T11:43:56.976-0300] {logging_mixin.py:188} INFO - [2023-12-31T11:43:56.975-0300] {dagbag.py:538} INFO - Filling up the DagBag from /home/felipe/airflow/dags/04_time_delta.py
[2023-12-31T11:43:57.006-0300] {logging_mixin.py:188} INFO - [2023-12-31T11:43:57.004-0300] {dagbag.py:348} ERROR - Failed to import: /home/felipe/airflow/dags/04_time_delta.py
Traceback (most recent call last):
  File "/home/felipe/.local/lib/python3.10/site-packages/airflow/models/dagbag.py", line 344, in parse
    loader.exec_module(new_module)
  File "<frozen importlib._bootstrap_external>", line 883, in exec_module
  File "<frozen importlib._bootstrap>", line 241, in _call_with_frames_removed
  File "/home/felipe/airflow/dags/04_time_delta.py", line 4, in <module>
    import pandas as pd
ModuleNotFoundError: No module named 'pandas'
[2023-12-31T11:43:57.014-0300] {processor.py:842} WARNING - No viable dags retrieved from /home/felipe/airflow/dags/04_time_delta.py
[2023-12-31T11:43:57.145-0300] {processor.py:183} INFO - Processing /home/felipe/airflow/dags/04_time_delta.py took 0.200 seconds
[2023-12-31T11:45:38.414-0300] {processor.py:161} INFO - Started process (PID=35305) to work on /home/felipe/airflow/dags/04_time_delta.py
[2023-12-31T11:45:38.424-0300] {processor.py:830} INFO - Processing file /home/felipe/airflow/dags/04_time_delta.py for tasks to queue
[2023-12-31T11:45:38.434-0300] {logging_mixin.py:188} INFO - [2023-12-31T11:45:38.426-0300] {dagbag.py:538} INFO - Filling up the DagBag from /home/felipe/airflow/dags/04_time_delta.py
[2023-12-31T11:45:38.455-0300] {logging_mixin.py:188} INFO - [2023-12-31T11:45:38.446-0300] {dagbag.py:348} ERROR - Failed to import: /home/felipe/airflow/dags/04_time_delta.py
Traceback (most recent call last):
  File "/home/felipe/.local/lib/python3.10/site-packages/airflow/models/dagbag.py", line 344, in parse
    loader.exec_module(new_module)
  File "<frozen importlib._bootstrap_external>", line 883, in exec_module
  File "<frozen importlib._bootstrap>", line 241, in _call_with_frames_removed
  File "/home/felipe/airflow/dags/04_time_delta.py", line 4, in <module>
    import pandas as pd
ModuleNotFoundError: No module named 'pandas'
[2023-12-31T11:45:38.455-0300] {processor.py:842} WARNING - No viable dags retrieved from /home/felipe/airflow/dags/04_time_delta.py
[2023-12-31T11:45:38.635-0300] {processor.py:183} INFO - Processing /home/felipe/airflow/dags/04_time_delta.py took 0.251 seconds
[2023-12-31T11:47:15.405-0300] {processor.py:161} INFO - Started process (PID=35432) to work on /home/felipe/airflow/dags/04_time_delta.py
[2023-12-31T11:47:15.416-0300] {processor.py:830} INFO - Processing file /home/felipe/airflow/dags/04_time_delta.py for tasks to queue
[2023-12-31T11:47:15.426-0300] {logging_mixin.py:188} INFO - [2023-12-31T11:47:15.425-0300] {dagbag.py:538} INFO - Filling up the DagBag from /home/felipe/airflow/dags/04_time_delta.py
[2023-12-31T11:47:15.474-0300] {logging_mixin.py:188} INFO - [2023-12-31T11:47:15.455-0300] {dagbag.py:348} ERROR - Failed to import: /home/felipe/airflow/dags/04_time_delta.py
Traceback (most recent call last):
  File "/home/felipe/.local/lib/python3.10/site-packages/airflow/models/dagbag.py", line 344, in parse
    loader.exec_module(new_module)
  File "<frozen importlib._bootstrap_external>", line 883, in exec_module
  File "<frozen importlib._bootstrap>", line 241, in _call_with_frames_removed
  File "/home/felipe/airflow/dags/04_time_delta.py", line 4, in <module>
    import pandas as pd
ModuleNotFoundError: No module named 'pandas'
[2023-12-31T11:47:15.475-0300] {processor.py:842} WARNING - No viable dags retrieved from /home/felipe/airflow/dags/04_time_delta.py
[2023-12-31T11:47:15.664-0300] {processor.py:183} INFO - Processing /home/felipe/airflow/dags/04_time_delta.py took 0.288 seconds
[2023-12-31T11:49:28.954-0300] {processor.py:161} INFO - Started process (PID=35588) to work on /home/felipe/airflow/dags/04_time_delta.py
[2023-12-31T11:49:28.966-0300] {processor.py:830} INFO - Processing file /home/felipe/airflow/dags/04_time_delta.py for tasks to queue
[2023-12-31T11:49:28.986-0300] {logging_mixin.py:188} INFO - [2023-12-31T11:49:28.976-0300] {dagbag.py:538} INFO - Filling up the DagBag from /home/felipe/airflow/dags/04_time_delta.py
[2023-12-31T11:49:29.024-0300] {logging_mixin.py:188} INFO - [2023-12-31T11:49:29.014-0300] {dagbag.py:348} ERROR - Failed to import: /home/felipe/airflow/dags/04_time_delta.py
Traceback (most recent call last):
  File "/home/felipe/.local/lib/python3.10/site-packages/airflow/models/dagbag.py", line 344, in parse
    loader.exec_module(new_module)
  File "<frozen importlib._bootstrap_external>", line 883, in exec_module
  File "<frozen importlib._bootstrap>", line 241, in _call_with_frames_removed
  File "/home/felipe/airflow/dags/04_time_delta.py", line 4, in <module>
    import pandas as pd
ModuleNotFoundError: No module named 'pandas'
[2023-12-31T11:49:29.025-0300] {processor.py:842} WARNING - No viable dags retrieved from /home/felipe/airflow/dags/04_time_delta.py
[2023-12-31T11:49:29.226-0300] {processor.py:183} INFO - Processing /home/felipe/airflow/dags/04_time_delta.py took 0.310 seconds
[2023-12-31T11:51:38.865-0300] {processor.py:161} INFO - Started process (PID=35742) to work on /home/felipe/airflow/dags/04_time_delta.py
[2023-12-31T11:51:38.884-0300] {processor.py:830} INFO - Processing file /home/felipe/airflow/dags/04_time_delta.py for tasks to queue
[2023-12-31T11:51:38.914-0300] {logging_mixin.py:188} INFO - [2023-12-31T11:51:38.894-0300] {dagbag.py:538} INFO - Filling up the DagBag from /home/felipe/airflow/dags/04_time_delta.py
[2023-12-31T11:51:38.946-0300] {logging_mixin.py:188} INFO - [2023-12-31T11:51:38.944-0300] {dagbag.py:348} ERROR - Failed to import: /home/felipe/airflow/dags/04_time_delta.py
Traceback (most recent call last):
  File "/home/felipe/.local/lib/python3.10/site-packages/airflow/models/dagbag.py", line 344, in parse
    loader.exec_module(new_module)
  File "<frozen importlib._bootstrap_external>", line 883, in exec_module
  File "<frozen importlib._bootstrap>", line 241, in _call_with_frames_removed
  File "/home/felipe/airflow/dags/04_time_delta.py", line 4, in <module>
    import pandas as pd
ModuleNotFoundError: No module named 'pandas'
[2023-12-31T11:51:38.955-0300] {processor.py:842} WARNING - No viable dags retrieved from /home/felipe/airflow/dags/04_time_delta.py
[2023-12-31T11:51:39.145-0300] {processor.py:183} INFO - Processing /home/felipe/airflow/dags/04_time_delta.py took 0.330 seconds
[2023-12-31T11:54:23.005-0300] {processor.py:161} INFO - Started process (PID=35872) to work on /home/felipe/airflow/dags/04_time_delta.py
[2023-12-31T11:54:23.015-0300] {processor.py:830} INFO - Processing file /home/felipe/airflow/dags/04_time_delta.py for tasks to queue
[2023-12-31T11:54:23.025-0300] {logging_mixin.py:188} INFO - [2023-12-31T11:54:23.024-0300] {dagbag.py:538} INFO - Filling up the DagBag from /home/felipe/airflow/dags/04_time_delta.py
[2023-12-31T11:54:23.066-0300] {logging_mixin.py:188} INFO - [2023-12-31T11:54:23.054-0300] {dagbag.py:348} ERROR - Failed to import: /home/felipe/airflow/dags/04_time_delta.py
Traceback (most recent call last):
  File "/home/felipe/.local/lib/python3.10/site-packages/airflow/models/dagbag.py", line 344, in parse
    loader.exec_module(new_module)
  File "<frozen importlib._bootstrap_external>", line 883, in exec_module
  File "<frozen importlib._bootstrap>", line 241, in _call_with_frames_removed
  File "/home/felipe/airflow/dags/04_time_delta.py", line 4, in <module>
    import pandas as pd
ModuleNotFoundError: No module named 'pandas'
[2023-12-31T11:54:23.075-0300] {processor.py:842} WARNING - No viable dags retrieved from /home/felipe/airflow/dags/04_time_delta.py
[2023-12-31T11:54:23.316-0300] {processor.py:183} INFO - Processing /home/felipe/airflow/dags/04_time_delta.py took 0.331 seconds
[2023-12-31T11:56:14.875-0300] {processor.py:161} INFO - Started process (PID=36007) to work on /home/felipe/airflow/dags/04_time_delta.py
[2023-12-31T11:56:14.885-0300] {processor.py:830} INFO - Processing file /home/felipe/airflow/dags/04_time_delta.py for tasks to queue
[2023-12-31T11:56:14.895-0300] {logging_mixin.py:188} INFO - [2023-12-31T11:56:14.894-0300] {dagbag.py:538} INFO - Filling up the DagBag from /home/felipe/airflow/dags/04_time_delta.py
[2023-12-31T11:56:14.934-0300] {logging_mixin.py:188} INFO - [2023-12-31T11:56:14.924-0300] {dagbag.py:348} ERROR - Failed to import: /home/felipe/airflow/dags/04_time_delta.py
Traceback (most recent call last):
  File "/home/felipe/.local/lib/python3.10/site-packages/airflow/models/dagbag.py", line 344, in parse
    loader.exec_module(new_module)
  File "<frozen importlib._bootstrap_external>", line 883, in exec_module
  File "<frozen importlib._bootstrap>", line 241, in _call_with_frames_removed
  File "/home/felipe/airflow/dags/04_time_delta.py", line 4, in <module>
    import pandas as pd
ModuleNotFoundError: No module named 'pandas'
[2023-12-31T11:56:14.935-0300] {processor.py:842} WARNING - No viable dags retrieved from /home/felipe/airflow/dags/04_time_delta.py
[2023-12-31T11:56:15.145-0300] {processor.py:183} INFO - Processing /home/felipe/airflow/dags/04_time_delta.py took 0.300 seconds
[2023-12-31T11:57:59.765-0300] {processor.py:161} INFO - Started process (PID=36112) to work on /home/felipe/airflow/dags/04_time_delta.py
[2023-12-31T11:57:59.775-0300] {processor.py:830} INFO - Processing file /home/felipe/airflow/dags/04_time_delta.py for tasks to queue
[2023-12-31T11:57:59.784-0300] {logging_mixin.py:188} INFO - [2023-12-31T11:57:59.784-0300] {dagbag.py:538} INFO - Filling up the DagBag from /home/felipe/airflow/dags/04_time_delta.py
[2023-12-31T11:57:59.805-0300] {logging_mixin.py:188} INFO - [2023-12-31T11:57:59.804-0300] {dagbag.py:348} ERROR - Failed to import: /home/felipe/airflow/dags/04_time_delta.py
Traceback (most recent call last):
  File "/home/felipe/.local/lib/python3.10/site-packages/airflow/models/dagbag.py", line 344, in parse
    loader.exec_module(new_module)
  File "<frozen importlib._bootstrap_external>", line 883, in exec_module
  File "<frozen importlib._bootstrap>", line 241, in _call_with_frames_removed
  File "/home/felipe/airflow/dags/04_time_delta.py", line 4, in <module>
    import pandas as pd
ModuleNotFoundError: No module named 'pandas'
[2023-12-31T11:57:59.814-0300] {processor.py:842} WARNING - No viable dags retrieved from /home/felipe/airflow/dags/04_time_delta.py
[2023-12-31T11:58:00.024-0300] {processor.py:183} INFO - Processing /home/felipe/airflow/dags/04_time_delta.py took 0.289 seconds
[2023-12-31T11:59:46.385-0300] {processor.py:161} INFO - Started process (PID=36217) to work on /home/felipe/airflow/dags/04_time_delta.py
[2023-12-31T11:59:46.395-0300] {processor.py:830} INFO - Processing file /home/felipe/airflow/dags/04_time_delta.py for tasks to queue
[2023-12-31T11:59:46.405-0300] {logging_mixin.py:188} INFO - [2023-12-31T11:59:46.404-0300] {dagbag.py:538} INFO - Filling up the DagBag from /home/felipe/airflow/dags/04_time_delta.py
[2023-12-31T11:59:46.434-0300] {logging_mixin.py:188} INFO - [2023-12-31T11:59:46.424-0300] {dagbag.py:348} ERROR - Failed to import: /home/felipe/airflow/dags/04_time_delta.py
Traceback (most recent call last):
  File "/home/felipe/.local/lib/python3.10/site-packages/airflow/models/dagbag.py", line 344, in parse
    loader.exec_module(new_module)
  File "<frozen importlib._bootstrap_external>", line 883, in exec_module
  File "<frozen importlib._bootstrap>", line 241, in _call_with_frames_removed
  File "/home/felipe/airflow/dags/04_time_delta.py", line 4, in <module>
    import pandas as pd
ModuleNotFoundError: No module named 'pandas'
[2023-12-31T11:59:46.434-0300] {processor.py:842} WARNING - No viable dags retrieved from /home/felipe/airflow/dags/04_time_delta.py
[2023-12-31T11:59:46.625-0300] {processor.py:183} INFO - Processing /home/felipe/airflow/dags/04_time_delta.py took 0.269 seconds
[2023-12-31T12:01:35.905-0300] {processor.py:161} INFO - Started process (PID=36349) to work on /home/felipe/airflow/dags/04_time_delta.py
[2023-12-31T12:01:35.915-0300] {processor.py:830} INFO - Processing file /home/felipe/airflow/dags/04_time_delta.py for tasks to queue
[2023-12-31T12:01:35.934-0300] {logging_mixin.py:188} INFO - [2023-12-31T12:01:35.925-0300] {dagbag.py:538} INFO - Filling up the DagBag from /home/felipe/airflow/dags/04_time_delta.py
[2023-12-31T12:01:35.995-0300] {logging_mixin.py:188} INFO - [2023-12-31T12:01:35.974-0300] {dagbag.py:348} ERROR - Failed to import: /home/felipe/airflow/dags/04_time_delta.py
Traceback (most recent call last):
  File "/home/felipe/.local/lib/python3.10/site-packages/airflow/models/dagbag.py", line 344, in parse
    loader.exec_module(new_module)
  File "<frozen importlib._bootstrap_external>", line 883, in exec_module
  File "<frozen importlib._bootstrap>", line 241, in _call_with_frames_removed
  File "/home/felipe/airflow/dags/04_time_delta.py", line 4, in <module>
    import pandas as pd
ModuleNotFoundError: No module named 'pandas'
[2023-12-31T12:01:35.995-0300] {processor.py:842} WARNING - No viable dags retrieved from /home/felipe/airflow/dags/04_time_delta.py
[2023-12-31T12:01:36.225-0300] {processor.py:183} INFO - Processing /home/felipe/airflow/dags/04_time_delta.py took 0.359 seconds
[2023-12-31T12:03:35.345-0300] {processor.py:161} INFO - Started process (PID=36459) to work on /home/felipe/airflow/dags/04_time_delta.py
[2023-12-31T12:03:35.365-0300] {processor.py:830} INFO - Processing file /home/felipe/airflow/dags/04_time_delta.py for tasks to queue
[2023-12-31T12:03:35.384-0300] {logging_mixin.py:188} INFO - [2023-12-31T12:03:35.374-0300] {dagbag.py:538} INFO - Filling up the DagBag from /home/felipe/airflow/dags/04_time_delta.py
[2023-12-31T12:03:35.425-0300] {logging_mixin.py:188} INFO - [2023-12-31T12:03:35.415-0300] {dagbag.py:348} ERROR - Failed to import: /home/felipe/airflow/dags/04_time_delta.py
Traceback (most recent call last):
  File "/home/felipe/.local/lib/python3.10/site-packages/airflow/models/dagbag.py", line 344, in parse
    loader.exec_module(new_module)
  File "<frozen importlib._bootstrap_external>", line 883, in exec_module
  File "<frozen importlib._bootstrap>", line 241, in _call_with_frames_removed
  File "/home/felipe/airflow/dags/04_time_delta.py", line 4, in <module>
    import pandas as pd
ModuleNotFoundError: No module named 'pandas'
[2023-12-31T12:03:35.445-0300] {processor.py:842} WARNING - No viable dags retrieved from /home/felipe/airflow/dags/04_time_delta.py
[2023-12-31T12:03:35.815-0300] {processor.py:183} INFO - Processing /home/felipe/airflow/dags/04_time_delta.py took 0.530 seconds
[2023-12-31T12:07:00.434-0300] {processor.py:161} INFO - Started process (PID=36717) to work on /home/felipe/airflow/dags/04_time_delta.py
[2023-12-31T12:07:00.445-0300] {processor.py:830} INFO - Processing file /home/felipe/airflow/dags/04_time_delta.py for tasks to queue
[2023-12-31T12:07:00.465-0300] {logging_mixin.py:188} INFO - [2023-12-31T12:07:00.464-0300] {dagbag.py:538} INFO - Filling up the DagBag from /home/felipe/airflow/dags/04_time_delta.py
[2023-12-31T12:07:00.554-0300] {logging_mixin.py:188} INFO - [2023-12-31T12:07:00.515-0300] {dagbag.py:348} ERROR - Failed to import: /home/felipe/airflow/dags/04_time_delta.py
Traceback (most recent call last):
  File "/home/felipe/.local/lib/python3.10/site-packages/airflow/models/dagbag.py", line 344, in parse
    loader.exec_module(new_module)
  File "<frozen importlib._bootstrap_external>", line 883, in exec_module
  File "<frozen importlib._bootstrap>", line 241, in _call_with_frames_removed
  File "/home/felipe/airflow/dags/04_time_delta.py", line 4, in <module>
    import pandas as pd
ModuleNotFoundError: No module named 'pandas'
[2023-12-31T12:07:00.565-0300] {processor.py:842} WARNING - No viable dags retrieved from /home/felipe/airflow/dags/04_time_delta.py
[2023-12-31T12:07:01.104-0300] {processor.py:183} INFO - Processing /home/felipe/airflow/dags/04_time_delta.py took 0.740 seconds
[2023-12-31T12:10:31.934-0300] {processor.py:161} INFO - Started process (PID=37106) to work on /home/felipe/airflow/dags/04_time_delta.py
[2023-12-31T12:10:31.954-0300] {processor.py:830} INFO - Processing file /home/felipe/airflow/dags/04_time_delta.py for tasks to queue
[2023-12-31T12:10:31.974-0300] {logging_mixin.py:188} INFO - [2023-12-31T12:10:31.964-0300] {dagbag.py:538} INFO - Filling up the DagBag from /home/felipe/airflow/dags/04_time_delta.py
[2023-12-31T12:10:32.045-0300] {logging_mixin.py:188} INFO - [2023-12-31T12:10:32.024-0300] {dagbag.py:348} ERROR - Failed to import: /home/felipe/airflow/dags/04_time_delta.py
Traceback (most recent call last):
  File "/home/felipe/.local/lib/python3.10/site-packages/airflow/models/dagbag.py", line 344, in parse
    loader.exec_module(new_module)
  File "<frozen importlib._bootstrap_external>", line 883, in exec_module
  File "<frozen importlib._bootstrap>", line 241, in _call_with_frames_removed
  File "/home/felipe/airflow/dags/04_time_delta.py", line 4, in <module>
    import pandas as pd
ModuleNotFoundError: No module named 'pandas'
[2023-12-31T12:10:32.064-0300] {processor.py:842} WARNING - No viable dags retrieved from /home/felipe/airflow/dags/04_time_delta.py
[2023-12-31T12:10:34.075-0300] {processor.py:183} INFO - Processing /home/felipe/airflow/dags/04_time_delta.py took 2.181 seconds
[2023-12-31T12:11:48.115-0300] {processor.py:161} INFO - Started process (PID=37204) to work on /home/felipe/airflow/dags/04_time_delta.py
[2023-12-31T12:11:48.135-0300] {processor.py:830} INFO - Processing file /home/felipe/airflow/dags/04_time_delta.py for tasks to queue
[2023-12-31T12:11:48.165-0300] {logging_mixin.py:188} INFO - [2023-12-31T12:11:48.155-0300] {dagbag.py:538} INFO - Filling up the DagBag from /home/felipe/airflow/dags/04_time_delta.py
[2023-12-31T12:11:48.245-0300] {logging_mixin.py:188} INFO - [2023-12-31T12:11:48.224-0300] {dagbag.py:348} ERROR - Failed to import: /home/felipe/airflow/dags/04_time_delta.py
Traceback (most recent call last):
  File "/home/felipe/.local/lib/python3.10/site-packages/airflow/models/dagbag.py", line 344, in parse
    loader.exec_module(new_module)
  File "<frozen importlib._bootstrap_external>", line 883, in exec_module
  File "<frozen importlib._bootstrap>", line 241, in _call_with_frames_removed
  File "/home/felipe/airflow/dags/04_time_delta.py", line 4, in <module>
    import pandas as pd
ModuleNotFoundError: No module named 'pandas'
[2023-12-31T12:11:48.255-0300] {processor.py:842} WARNING - No viable dags retrieved from /home/felipe/airflow/dags/04_time_delta.py
[2023-12-31T12:11:48.605-0300] {processor.py:183} INFO - Processing /home/felipe/airflow/dags/04_time_delta.py took 0.531 seconds
[2023-12-31T12:12:37.685-0300] {processor.py:161} INFO - Started process (PID=37277) to work on /home/felipe/airflow/dags/04_time_delta.py
[2023-12-31T12:12:37.705-0300] {processor.py:830} INFO - Processing file /home/felipe/airflow/dags/04_time_delta.py for tasks to queue
[2023-12-31T12:12:37.724-0300] {logging_mixin.py:188} INFO - [2023-12-31T12:12:37.715-0300] {dagbag.py:538} INFO - Filling up the DagBag from /home/felipe/airflow/dags/04_time_delta.py
[2023-12-31T12:12:37.764-0300] {logging_mixin.py:188} INFO - [2023-12-31T12:12:37.754-0300] {dagbag.py:348} ERROR - Failed to import: /home/felipe/airflow/dags/04_time_delta.py
Traceback (most recent call last):
  File "/home/felipe/.local/lib/python3.10/site-packages/airflow/models/dagbag.py", line 344, in parse
    loader.exec_module(new_module)
  File "<frozen importlib._bootstrap_external>", line 883, in exec_module
  File "<frozen importlib._bootstrap>", line 241, in _call_with_frames_removed
  File "/home/felipe/airflow/dags/04_time_delta.py", line 4, in <module>
    import pandas as pd
ModuleNotFoundError: No module named 'pandas'
[2023-12-31T12:12:37.774-0300] {processor.py:842} WARNING - No viable dags retrieved from /home/felipe/airflow/dags/04_time_delta.py
[2023-12-31T12:12:38.025-0300] {processor.py:183} INFO - Processing /home/felipe/airflow/dags/04_time_delta.py took 0.401 seconds
[2023-12-31T12:13:40.714-0300] {processor.py:161} INFO - Started process (PID=37359) to work on /home/felipe/airflow/dags/04_time_delta.py
[2023-12-31T12:13:40.734-0300] {processor.py:830} INFO - Processing file /home/felipe/airflow/dags/04_time_delta.py for tasks to queue
[2023-12-31T12:13:40.765-0300] {logging_mixin.py:188} INFO - [2023-12-31T12:13:40.754-0300] {dagbag.py:538} INFO - Filling up the DagBag from /home/felipe/airflow/dags/04_time_delta.py
[2023-12-31T12:13:40.825-0300] {logging_mixin.py:188} INFO - [2023-12-31T12:13:40.805-0300] {dagbag.py:348} ERROR - Failed to import: /home/felipe/airflow/dags/04_time_delta.py
Traceback (most recent call last):
  File "/home/felipe/.local/lib/python3.10/site-packages/airflow/models/dagbag.py", line 344, in parse
    loader.exec_module(new_module)
  File "<frozen importlib._bootstrap_external>", line 883, in exec_module
  File "<frozen importlib._bootstrap>", line 241, in _call_with_frames_removed
  File "/home/felipe/airflow/dags/04_time_delta.py", line 4, in <module>
    import pandas as pd
ModuleNotFoundError: No module named 'pandas'
[2023-12-31T12:13:40.844-0300] {processor.py:842} WARNING - No viable dags retrieved from /home/felipe/airflow/dags/04_time_delta.py
[2023-12-31T12:13:41.115-0300] {processor.py:183} INFO - Processing /home/felipe/airflow/dags/04_time_delta.py took 0.440 seconds
[2023-12-31T12:14:48.984-0300] {processor.py:161} INFO - Started process (PID=37470) to work on /home/felipe/airflow/dags/04_time_delta.py
[2023-12-31T12:14:49.004-0300] {processor.py:830} INFO - Processing file /home/felipe/airflow/dags/04_time_delta.py for tasks to queue
[2023-12-31T12:14:49.024-0300] {logging_mixin.py:188} INFO - [2023-12-31T12:14:49.014-0300] {dagbag.py:538} INFO - Filling up the DagBag from /home/felipe/airflow/dags/04_time_delta.py
[2023-12-31T12:14:49.074-0300] {logging_mixin.py:188} INFO - [2023-12-31T12:14:49.055-0300] {dagbag.py:348} ERROR - Failed to import: /home/felipe/airflow/dags/04_time_delta.py
Traceback (most recent call last):
  File "/home/felipe/.local/lib/python3.10/site-packages/airflow/models/dagbag.py", line 344, in parse
    loader.exec_module(new_module)
  File "<frozen importlib._bootstrap_external>", line 883, in exec_module
  File "<frozen importlib._bootstrap>", line 241, in _call_with_frames_removed
  File "/home/felipe/airflow/dags/04_time_delta.py", line 4, in <module>
    import pandas as pd
ModuleNotFoundError: No module named 'pandas'
[2023-12-31T12:14:49.084-0300] {processor.py:842} WARNING - No viable dags retrieved from /home/felipe/airflow/dags/04_time_delta.py
[2023-12-31T12:14:49.405-0300] {processor.py:183} INFO - Processing /home/felipe/airflow/dags/04_time_delta.py took 0.490 seconds
[2023-12-31T12:15:44.854-0300] {processor.py:161} INFO - Started process (PID=37546) to work on /home/felipe/airflow/dags/04_time_delta.py
[2023-12-31T12:15:44.874-0300] {processor.py:830} INFO - Processing file /home/felipe/airflow/dags/04_time_delta.py for tasks to queue
[2023-12-31T12:15:44.884-0300] {logging_mixin.py:188} INFO - [2023-12-31T12:15:44.875-0300] {dagbag.py:538} INFO - Filling up the DagBag from /home/felipe/airflow/dags/04_time_delta.py
[2023-12-31T12:15:44.925-0300] {logging_mixin.py:188} INFO - [2023-12-31T12:15:44.915-0300] {dagbag.py:348} ERROR - Failed to import: /home/felipe/airflow/dags/04_time_delta.py
Traceback (most recent call last):
  File "/home/felipe/.local/lib/python3.10/site-packages/airflow/models/dagbag.py", line 344, in parse
    loader.exec_module(new_module)
  File "<frozen importlib._bootstrap_external>", line 883, in exec_module
  File "<frozen importlib._bootstrap>", line 241, in _call_with_frames_removed
  File "/home/felipe/airflow/dags/04_time_delta.py", line 4, in <module>
    import pandas as pd
ModuleNotFoundError: No module named 'pandas'
[2023-12-31T12:15:44.934-0300] {processor.py:842} WARNING - No viable dags retrieved from /home/felipe/airflow/dags/04_time_delta.py
[2023-12-31T12:15:45.254-0300] {processor.py:183} INFO - Processing /home/felipe/airflow/dags/04_time_delta.py took 0.439 seconds
[2023-12-31T12:16:52.064-0300] {processor.py:161} INFO - Started process (PID=37631) to work on /home/felipe/airflow/dags/04_time_delta.py
[2023-12-31T12:16:52.084-0300] {processor.py:830} INFO - Processing file /home/felipe/airflow/dags/04_time_delta.py for tasks to queue
[2023-12-31T12:16:52.094-0300] {logging_mixin.py:188} INFO - [2023-12-31T12:16:52.094-0300] {dagbag.py:538} INFO - Filling up the DagBag from /home/felipe/airflow/dags/04_time_delta.py
[2023-12-31T12:16:52.145-0300] {logging_mixin.py:188} INFO - [2023-12-31T12:16:52.134-0300] {dagbag.py:348} ERROR - Failed to import: /home/felipe/airflow/dags/04_time_delta.py
Traceback (most recent call last):
  File "/home/felipe/.local/lib/python3.10/site-packages/airflow/models/dagbag.py", line 344, in parse
    loader.exec_module(new_module)
  File "<frozen importlib._bootstrap_external>", line 883, in exec_module
  File "<frozen importlib._bootstrap>", line 241, in _call_with_frames_removed
  File "/home/felipe/airflow/dags/04_time_delta.py", line 4, in <module>
    import pandas as pd
ModuleNotFoundError: No module named 'pandas'
[2023-12-31T12:16:52.155-0300] {processor.py:842} WARNING - No viable dags retrieved from /home/felipe/airflow/dags/04_time_delta.py
[2023-12-31T12:16:52.594-0300] {processor.py:183} INFO - Processing /home/felipe/airflow/dags/04_time_delta.py took 0.590 seconds
[2023-12-31T12:18:07.744-0300] {processor.py:161} INFO - Started process (PID=37732) to work on /home/felipe/airflow/dags/04_time_delta.py
[2023-12-31T12:18:07.765-0300] {processor.py:830} INFO - Processing file /home/felipe/airflow/dags/04_time_delta.py for tasks to queue
[2023-12-31T12:18:07.804-0300] {logging_mixin.py:188} INFO - [2023-12-31T12:18:07.794-0300] {dagbag.py:538} INFO - Filling up the DagBag from /home/felipe/airflow/dags/04_time_delta.py
[2023-12-31T12:18:07.904-0300] {logging_mixin.py:188} INFO - [2023-12-31T12:18:07.884-0300] {dagbag.py:348} ERROR - Failed to import: /home/felipe/airflow/dags/04_time_delta.py
Traceback (most recent call last):
  File "/home/felipe/.local/lib/python3.10/site-packages/airflow/models/dagbag.py", line 344, in parse
    loader.exec_module(new_module)
  File "<frozen importlib._bootstrap_external>", line 883, in exec_module
  File "<frozen importlib._bootstrap>", line 241, in _call_with_frames_removed
  File "/home/felipe/airflow/dags/04_time_delta.py", line 4, in <module>
    import pandas as pd
ModuleNotFoundError: No module named 'pandas'
[2023-12-31T12:18:07.914-0300] {processor.py:842} WARNING - No viable dags retrieved from /home/felipe/airflow/dags/04_time_delta.py
[2023-12-31T12:18:08.415-0300] {processor.py:183} INFO - Processing /home/felipe/airflow/dags/04_time_delta.py took 0.760 seconds
[2023-12-31T12:26:21.471-0300] {processor.py:161} INFO - Started process (PID=37982) to work on /home/felipe/airflow/dags/04_time_delta.py
[2023-12-31T12:26:21.491-0300] {processor.py:830} INFO - Processing file /home/felipe/airflow/dags/04_time_delta.py for tasks to queue
[2023-12-31T12:26:21.511-0300] {logging_mixin.py:188} INFO - [2023-12-31T12:26:21.501-0300] {dagbag.py:538} INFO - Filling up the DagBag from /home/felipe/airflow/dags/04_time_delta.py
[2023-12-31T12:26:21.591-0300] {logging_mixin.py:188} INFO - [2023-12-31T12:26:21.551-0300] {dagbag.py:348} ERROR - Failed to import: /home/felipe/airflow/dags/04_time_delta.py
Traceback (most recent call last):
  File "/home/felipe/.local/lib/python3.10/site-packages/airflow/models/dagbag.py", line 344, in parse
    loader.exec_module(new_module)
  File "<frozen importlib._bootstrap_external>", line 883, in exec_module
  File "<frozen importlib._bootstrap>", line 241, in _call_with_frames_removed
  File "/home/felipe/airflow/dags/04_time_delta.py", line 4, in <module>
    import pandas as pd
ModuleNotFoundError: No module named 'pandas'
[2023-12-31T12:26:21.601-0300] {processor.py:842} WARNING - No viable dags retrieved from /home/felipe/airflow/dags/04_time_delta.py
[2023-12-31T12:26:21.981-0300] {processor.py:183} INFO - Processing /home/felipe/airflow/dags/04_time_delta.py took 0.560 seconds
[2023-12-31T12:27:30.240-0300] {processor.py:161} INFO - Started process (PID=38055) to work on /home/felipe/airflow/dags/04_time_delta.py
[2023-12-31T12:27:30.261-0300] {processor.py:830} INFO - Processing file /home/felipe/airflow/dags/04_time_delta.py for tasks to queue
[2023-12-31T12:27:30.281-0300] {logging_mixin.py:188} INFO - [2023-12-31T12:27:30.271-0300] {dagbag.py:538} INFO - Filling up the DagBag from /home/felipe/airflow/dags/04_time_delta.py
[2023-12-31T12:27:30.401-0300] {logging_mixin.py:188} INFO - [2023-12-31T12:27:30.361-0300] {dagbag.py:348} ERROR - Failed to import: /home/felipe/airflow/dags/04_time_delta.py
Traceback (most recent call last):
  File "/home/felipe/.local/lib/python3.10/site-packages/airflow/models/dagbag.py", line 344, in parse
    loader.exec_module(new_module)
  File "<frozen importlib._bootstrap_external>", line 883, in exec_module
  File "<frozen importlib._bootstrap>", line 241, in _call_with_frames_removed
  File "/home/felipe/airflow/dags/04_time_delta.py", line 4, in <module>
    import pandas as pd
ModuleNotFoundError: No module named 'pandas'
[2023-12-31T12:27:30.411-0300] {processor.py:842} WARNING - No viable dags retrieved from /home/felipe/airflow/dags/04_time_delta.py
[2023-12-31T12:27:30.831-0300] {processor.py:183} INFO - Processing /home/felipe/airflow/dags/04_time_delta.py took 0.680 seconds
[2023-12-31T12:28:46.261-0300] {processor.py:161} INFO - Started process (PID=38111) to work on /home/felipe/airflow/dags/04_time_delta.py
[2023-12-31T12:28:46.300-0300] {processor.py:830} INFO - Processing file /home/felipe/airflow/dags/04_time_delta.py for tasks to queue
[2023-12-31T12:28:46.321-0300] {logging_mixin.py:188} INFO - [2023-12-31T12:28:46.311-0300] {dagbag.py:538} INFO - Filling up the DagBag from /home/felipe/airflow/dags/04_time_delta.py
[2023-12-31T12:28:46.421-0300] {logging_mixin.py:188} INFO - [2023-12-31T12:28:46.381-0300] {dagbag.py:348} ERROR - Failed to import: /home/felipe/airflow/dags/04_time_delta.py
Traceback (most recent call last):
  File "/home/felipe/.local/lib/python3.10/site-packages/airflow/models/dagbag.py", line 344, in parse
    loader.exec_module(new_module)
  File "<frozen importlib._bootstrap_external>", line 883, in exec_module
  File "<frozen importlib._bootstrap>", line 241, in _call_with_frames_removed
  File "/home/felipe/airflow/dags/04_time_delta.py", line 4, in <module>
    import pandas as pd
ModuleNotFoundError: No module named 'pandas'
[2023-12-31T12:28:46.440-0300] {processor.py:842} WARNING - No viable dags retrieved from /home/felipe/airflow/dags/04_time_delta.py
[2023-12-31T12:28:46.930-0300] {processor.py:183} INFO - Processing /home/felipe/airflow/dags/04_time_delta.py took 0.730 seconds
[2023-12-31T12:29:59.191-0300] {processor.py:161} INFO - Started process (PID=38168) to work on /home/felipe/airflow/dags/04_time_delta.py
[2023-12-31T12:29:59.221-0300] {processor.py:830} INFO - Processing file /home/felipe/airflow/dags/04_time_delta.py for tasks to queue
[2023-12-31T12:29:59.241-0300] {logging_mixin.py:188} INFO - [2023-12-31T12:29:59.231-0300] {dagbag.py:538} INFO - Filling up the DagBag from /home/felipe/airflow/dags/04_time_delta.py
[2023-12-31T12:29:59.320-0300] {logging_mixin.py:188} INFO - [2023-12-31T12:29:59.300-0300] {dagbag.py:348} ERROR - Failed to import: /home/felipe/airflow/dags/04_time_delta.py
Traceback (most recent call last):
  File "/home/felipe/.local/lib/python3.10/site-packages/airflow/models/dagbag.py", line 344, in parse
    loader.exec_module(new_module)
  File "<frozen importlib._bootstrap_external>", line 883, in exec_module
  File "<frozen importlib._bootstrap>", line 241, in _call_with_frames_removed
  File "/home/felipe/airflow/dags/04_time_delta.py", line 4, in <module>
    import pandas as pd
ModuleNotFoundError: No module named 'pandas'
[2023-12-31T12:29:59.330-0300] {processor.py:842} WARNING - No viable dags retrieved from /home/felipe/airflow/dags/04_time_delta.py
[2023-12-31T12:29:59.751-0300] {processor.py:183} INFO - Processing /home/felipe/airflow/dags/04_time_delta.py took 0.630 seconds
[2023-12-31T12:31:15.131-0300] {processor.py:161} INFO - Started process (PID=38243) to work on /home/felipe/airflow/dags/04_time_delta.py
[2023-12-31T12:31:15.161-0300] {processor.py:830} INFO - Processing file /home/felipe/airflow/dags/04_time_delta.py for tasks to queue
[2023-12-31T12:31:15.190-0300] {logging_mixin.py:188} INFO - [2023-12-31T12:31:15.180-0300] {dagbag.py:538} INFO - Filling up the DagBag from /home/felipe/airflow/dags/04_time_delta.py
[2023-12-31T12:31:15.260-0300] {logging_mixin.py:188} INFO - [2023-12-31T12:31:15.240-0300] {dagbag.py:348} ERROR - Failed to import: /home/felipe/airflow/dags/04_time_delta.py
Traceback (most recent call last):
  File "/home/felipe/.local/lib/python3.10/site-packages/airflow/models/dagbag.py", line 344, in parse
    loader.exec_module(new_module)
  File "<frozen importlib._bootstrap_external>", line 883, in exec_module
  File "<frozen importlib._bootstrap>", line 241, in _call_with_frames_removed
  File "/home/felipe/airflow/dags/04_time_delta.py", line 4, in <module>
    import pandas as pd
ModuleNotFoundError: No module named 'pandas'
[2023-12-31T12:31:15.270-0300] {processor.py:842} WARNING - No viable dags retrieved from /home/felipe/airflow/dags/04_time_delta.py
[2023-12-31T12:31:15.751-0300] {processor.py:183} INFO - Processing /home/felipe/airflow/dags/04_time_delta.py took 0.670 seconds
[2023-12-31T12:32:36.171-0300] {processor.py:161} INFO - Started process (PID=38297) to work on /home/felipe/airflow/dags/04_time_delta.py
[2023-12-31T12:32:36.201-0300] {processor.py:830} INFO - Processing file /home/felipe/airflow/dags/04_time_delta.py for tasks to queue
[2023-12-31T12:32:36.231-0300] {logging_mixin.py:188} INFO - [2023-12-31T12:32:36.230-0300] {dagbag.py:538} INFO - Filling up the DagBag from /home/felipe/airflow/dags/04_time_delta.py
[2023-12-31T12:32:36.330-0300] {logging_mixin.py:188} INFO - [2023-12-31T12:32:36.301-0300] {dagbag.py:348} ERROR - Failed to import: /home/felipe/airflow/dags/04_time_delta.py
Traceback (most recent call last):
  File "/home/felipe/.local/lib/python3.10/site-packages/airflow/models/dagbag.py", line 344, in parse
    loader.exec_module(new_module)
  File "<frozen importlib._bootstrap_external>", line 883, in exec_module
  File "<frozen importlib._bootstrap>", line 241, in _call_with_frames_removed
  File "/home/felipe/airflow/dags/04_time_delta.py", line 4, in <module>
    import pandas as pd
ModuleNotFoundError: No module named 'pandas'
[2023-12-31T12:32:36.341-0300] {processor.py:842} WARNING - No viable dags retrieved from /home/felipe/airflow/dags/04_time_delta.py
[2023-12-31T12:32:36.851-0300] {processor.py:183} INFO - Processing /home/felipe/airflow/dags/04_time_delta.py took 0.740 seconds
[2023-12-31T12:34:07.250-0300] {processor.py:161} INFO - Started process (PID=38352) to work on /home/felipe/airflow/dags/04_time_delta.py
[2023-12-31T12:34:07.280-0300] {processor.py:830} INFO - Processing file /home/felipe/airflow/dags/04_time_delta.py for tasks to queue
[2023-12-31T12:34:07.301-0300] {logging_mixin.py:188} INFO - [2023-12-31T12:34:07.291-0300] {dagbag.py:538} INFO - Filling up the DagBag from /home/felipe/airflow/dags/04_time_delta.py
[2023-12-31T12:34:07.420-0300] {logging_mixin.py:188} INFO - [2023-12-31T12:34:07.380-0300] {dagbag.py:348} ERROR - Failed to import: /home/felipe/airflow/dags/04_time_delta.py
Traceback (most recent call last):
  File "/home/felipe/.local/lib/python3.10/site-packages/airflow/models/dagbag.py", line 344, in parse
    loader.exec_module(new_module)
  File "<frozen importlib._bootstrap_external>", line 883, in exec_module
  File "<frozen importlib._bootstrap>", line 241, in _call_with_frames_removed
  File "/home/felipe/airflow/dags/04_time_delta.py", line 4, in <module>
    import pandas as pd
ModuleNotFoundError: No module named 'pandas'
[2023-12-31T12:34:07.441-0300] {processor.py:842} WARNING - No viable dags retrieved from /home/felipe/airflow/dags/04_time_delta.py
[2023-12-31T12:34:07.990-0300] {processor.py:183} INFO - Processing /home/felipe/airflow/dags/04_time_delta.py took 0.840 seconds
[2023-12-31T12:35:46.650-0300] {processor.py:161} INFO - Started process (PID=38442) to work on /home/felipe/airflow/dags/04_time_delta.py
[2023-12-31T12:35:46.671-0300] {processor.py:830} INFO - Processing file /home/felipe/airflow/dags/04_time_delta.py for tasks to queue
[2023-12-31T12:35:46.720-0300] {logging_mixin.py:188} INFO - [2023-12-31T12:35:46.700-0300] {dagbag.py:538} INFO - Filling up the DagBag from /home/felipe/airflow/dags/04_time_delta.py
[2023-12-31T12:35:46.841-0300] {logging_mixin.py:188} INFO - [2023-12-31T12:35:46.811-0300] {dagbag.py:348} ERROR - Failed to import: /home/felipe/airflow/dags/04_time_delta.py
Traceback (most recent call last):
  File "/home/felipe/.local/lib/python3.10/site-packages/airflow/models/dagbag.py", line 344, in parse
    loader.exec_module(new_module)
  File "<frozen importlib._bootstrap_external>", line 883, in exec_module
  File "<frozen importlib._bootstrap>", line 241, in _call_with_frames_removed
  File "/home/felipe/airflow/dags/04_time_delta.py", line 4, in <module>
    import pandas as pd
ModuleNotFoundError: No module named 'pandas'
[2023-12-31T12:35:46.860-0300] {processor.py:842} WARNING - No viable dags retrieved from /home/felipe/airflow/dags/04_time_delta.py
[2023-12-31T12:35:47.491-0300] {processor.py:183} INFO - Processing /home/felipe/airflow/dags/04_time_delta.py took 0.930 seconds
[2023-12-31T12:37:55.950-0300] {processor.py:161} INFO - Started process (PID=38511) to work on /home/felipe/airflow/dags/04_time_delta.py
[2023-12-31T12:37:55.990-0300] {processor.py:830} INFO - Processing file /home/felipe/airflow/dags/04_time_delta.py for tasks to queue
[2023-12-31T12:37:56.040-0300] {logging_mixin.py:188} INFO - [2023-12-31T12:37:56.030-0300] {dagbag.py:538} INFO - Filling up the DagBag from /home/felipe/airflow/dags/04_time_delta.py
[2023-12-31T12:37:56.240-0300] {logging_mixin.py:188} INFO - [2023-12-31T12:37:56.170-0300] {dagbag.py:348} ERROR - Failed to import: /home/felipe/airflow/dags/04_time_delta.py
Traceback (most recent call last):
  File "/home/felipe/.local/lib/python3.10/site-packages/airflow/models/dagbag.py", line 344, in parse
    loader.exec_module(new_module)
  File "<frozen importlib._bootstrap_external>", line 883, in exec_module
  File "<frozen importlib._bootstrap>", line 241, in _call_with_frames_removed
  File "/home/felipe/airflow/dags/04_time_delta.py", line 4, in <module>
    import pandas as pd
ModuleNotFoundError: No module named 'pandas'
[2023-12-31T12:37:56.270-0300] {processor.py:842} WARNING - No viable dags retrieved from /home/felipe/airflow/dags/04_time_delta.py
[2023-12-31T12:37:57.210-0300] {processor.py:183} INFO - Processing /home/felipe/airflow/dags/04_time_delta.py took 1.420 seconds
[2023-12-31T12:49:22.307-0300] {processor.py:161} INFO - Started process (PID=38823) to work on /home/felipe/airflow/dags/04_time_delta.py
[2023-12-31T12:49:22.388-0300] {processor.py:830} INFO - Processing file /home/felipe/airflow/dags/04_time_delta.py for tasks to queue
[2023-12-31T12:49:22.518-0300] {logging_mixin.py:188} INFO - [2023-12-31T12:49:22.478-0300] {dagbag.py:538} INFO - Filling up the DagBag from /home/felipe/airflow/dags/04_time_delta.py
[2023-12-31T12:49:22.937-0300] {logging_mixin.py:188} INFO - [2023-12-31T12:49:22.838-0300] {dagbag.py:348} ERROR - Failed to import: /home/felipe/airflow/dags/04_time_delta.py
Traceback (most recent call last):
  File "/home/felipe/.local/lib/python3.10/site-packages/airflow/models/dagbag.py", line 344, in parse
    loader.exec_module(new_module)
  File "<frozen importlib._bootstrap_external>", line 883, in exec_module
  File "<frozen importlib._bootstrap>", line 241, in _call_with_frames_removed
  File "/home/felipe/airflow/dags/04_time_delta.py", line 4, in <module>
    import pandas as pd
ModuleNotFoundError: No module named 'pandas'
[2023-12-31T12:49:22.998-0300] {processor.py:842} WARNING - No viable dags retrieved from /home/felipe/airflow/dags/04_time_delta.py
[2023-12-31T12:49:24.898-0300] {processor.py:183} INFO - Processing /home/felipe/airflow/dags/04_time_delta.py took 2.900 seconds
