[2023-12-31T09:36:42.320-0300] {processor.py:161} INFO - Started process (PID=31967) to work on /home/felipe/airflow/dags/05_query_with_dates.py
[2023-12-31T09:36:42.326-0300] {processor.py:830} INFO - Processing file /home/felipe/airflow/dags/05_query_with_dates.py for tasks to queue
[2023-12-31T09:36:42.328-0300] {logging_mixin.py:188} INFO - [2023-12-31T09:36:42.327-0300] {dagbag.py:538} INFO - Filling up the DagBag from /home/felipe/airflow/dags/05_query_with_dates.py
[2023-12-31T09:36:42.338-0300] {logging_mixin.py:188} INFO - [2023-12-31T09:36:42.336-0300] {dagbag.py:348} ERROR - Failed to import: /home/felipe/airflow/dags/05_query_with_dates.py
Traceback (most recent call last):
  File "/home/felipe/.local/lib/python3.10/site-packages/airflow/models/dagbag.py", line 344, in parse
    loader.exec_module(new_module)
  File "<frozen importlib._bootstrap_external>", line 883, in exec_module
  File "<frozen importlib._bootstrap>", line 241, in _call_with_frames_removed
  File "/home/felipe/airflow/dags/05_query_with_dates.py", line 4, in <module>
    import pandas as pd
ModuleNotFoundError: No module named 'pandas'
[2023-12-31T09:36:42.338-0300] {processor.py:842} WARNING - No viable dags retrieved from /home/felipe/airflow/dags/05_query_with_dates.py
[2023-12-31T09:36:42.397-0300] {processor.py:183} INFO - Processing /home/felipe/airflow/dags/05_query_with_dates.py took 0.080 seconds
[2023-12-31T09:38:33.606-0300] {processor.py:161} INFO - Started process (PID=32173) to work on /home/felipe/airflow/dags/05_query_with_dates.py
[2023-12-31T09:38:33.609-0300] {processor.py:830} INFO - Processing file /home/felipe/airflow/dags/05_query_with_dates.py for tasks to queue
[2023-12-31T09:38:33.617-0300] {logging_mixin.py:188} INFO - [2023-12-31T09:38:33.616-0300] {dagbag.py:538} INFO - Filling up the DagBag from /home/felipe/airflow/dags/05_query_with_dates.py
[2023-12-31T09:38:33.628-0300] {logging_mixin.py:188} INFO - [2023-12-31T09:38:33.627-0300] {dagbag.py:348} ERROR - Failed to import: /home/felipe/airflow/dags/05_query_with_dates.py
Traceback (most recent call last):
  File "/home/felipe/.local/lib/python3.10/site-packages/airflow/models/dagbag.py", line 344, in parse
    loader.exec_module(new_module)
  File "<frozen importlib._bootstrap_external>", line 883, in exec_module
  File "<frozen importlib._bootstrap>", line 241, in _call_with_frames_removed
  File "/home/felipe/airflow/dags/05_query_with_dates.py", line 4, in <module>
    import pandas as pd
ModuleNotFoundError: No module named 'pandas'
[2023-12-31T09:38:33.629-0300] {processor.py:842} WARNING - No viable dags retrieved from /home/felipe/airflow/dags/05_query_with_dates.py
[2023-12-31T09:38:33.759-0300] {processor.py:183} INFO - Processing /home/felipe/airflow/dags/05_query_with_dates.py took 0.170 seconds
[2023-12-31T09:52:02.587-0300] {processor.py:161} INFO - Started process (PID=32773) to work on /home/felipe/airflow/dags/05_query_with_dates.py
[2023-12-31T09:52:02.589-0300] {processor.py:830} INFO - Processing file /home/felipe/airflow/dags/05_query_with_dates.py for tasks to queue
[2023-12-31T09:52:02.598-0300] {logging_mixin.py:188} INFO - [2023-12-31T09:52:02.597-0300] {dagbag.py:538} INFO - Filling up the DagBag from /home/felipe/airflow/dags/05_query_with_dates.py
[2023-12-31T09:52:02.609-0300] {logging_mixin.py:188} INFO - [2023-12-31T09:52:02.608-0300] {dagbag.py:348} ERROR - Failed to import: /home/felipe/airflow/dags/05_query_with_dates.py
Traceback (most recent call last):
  File "/home/felipe/.local/lib/python3.10/site-packages/airflow/models/dagbag.py", line 344, in parse
    loader.exec_module(new_module)
  File "<frozen importlib._bootstrap_external>", line 883, in exec_module
  File "<frozen importlib._bootstrap>", line 241, in _call_with_frames_removed
  File "/home/felipe/airflow/dags/05_query_with_dates.py", line 4, in <module>
    import pandas as pd
ModuleNotFoundError: No module named 'pandas'
[2023-12-31T09:52:02.610-0300] {processor.py:842} WARNING - No viable dags retrieved from /home/felipe/airflow/dags/05_query_with_dates.py
[2023-12-31T09:52:02.770-0300] {processor.py:183} INFO - Processing /home/felipe/airflow/dags/05_query_with_dates.py took 0.200 seconds
[2023-12-31T09:55:20.959-0300] {processor.py:161} INFO - Started process (PID=32929) to work on /home/felipe/airflow/dags/05_query_with_dates.py
[2023-12-31T09:55:20.968-0300] {processor.py:830} INFO - Processing file /home/felipe/airflow/dags/05_query_with_dates.py for tasks to queue
[2023-12-31T09:55:20.978-0300] {logging_mixin.py:188} INFO - [2023-12-31T09:55:20.977-0300] {dagbag.py:538} INFO - Filling up the DagBag from /home/felipe/airflow/dags/05_query_with_dates.py
[2023-12-31T09:55:21.009-0300] {logging_mixin.py:188} INFO - [2023-12-31T09:55:21.006-0300] {dagbag.py:348} ERROR - Failed to import: /home/felipe/airflow/dags/05_query_with_dates.py
Traceback (most recent call last):
  File "/home/felipe/.local/lib/python3.10/site-packages/airflow/models/dagbag.py", line 344, in parse
    loader.exec_module(new_module)
  File "<frozen importlib._bootstrap_external>", line 883, in exec_module
  File "<frozen importlib._bootstrap>", line 241, in _call_with_frames_removed
  File "/home/felipe/airflow/dags/05_query_with_dates.py", line 4, in <module>
    import pandas as pd
ModuleNotFoundError: No module named 'pandas'
[2023-12-31T09:55:21.017-0300] {processor.py:842} WARNING - No viable dags retrieved from /home/felipe/airflow/dags/05_query_with_dates.py
[2023-12-31T09:55:21.269-0300] {processor.py:183} INFO - Processing /home/felipe/airflow/dags/05_query_with_dates.py took 0.330 seconds
[2023-12-31T09:59:56.679-0300] {processor.py:161} INFO - Started process (PID=33146) to work on /home/felipe/airflow/dags/05_query_with_dates.py
[2023-12-31T09:59:56.688-0300] {processor.py:830} INFO - Processing file /home/felipe/airflow/dags/05_query_with_dates.py for tasks to queue
[2023-12-31T09:59:56.696-0300] {logging_mixin.py:188} INFO - [2023-12-31T09:59:56.689-0300] {dagbag.py:538} INFO - Filling up the DagBag from /home/felipe/airflow/dags/05_query_with_dates.py
[2023-12-31T09:59:56.737-0300] {logging_mixin.py:188} INFO - [2023-12-31T09:59:56.719-0300] {dagbag.py:348} ERROR - Failed to import: /home/felipe/airflow/dags/05_query_with_dates.py
Traceback (most recent call last):
  File "/home/felipe/.local/lib/python3.10/site-packages/airflow/models/dagbag.py", line 344, in parse
    loader.exec_module(new_module)
  File "<frozen importlib._bootstrap_external>", line 883, in exec_module
  File "<frozen importlib._bootstrap>", line 241, in _call_with_frames_removed
  File "/home/felipe/airflow/dags/05_query_with_dates.py", line 4, in <module>
    import pandas as pd
ModuleNotFoundError: No module named 'pandas'
[2023-12-31T09:59:56.738-0300] {processor.py:842} WARNING - No viable dags retrieved from /home/felipe/airflow/dags/05_query_with_dates.py
[2023-12-31T09:59:56.839-0300] {processor.py:183} INFO - Processing /home/felipe/airflow/dags/05_query_with_dates.py took 0.171 seconds
[2023-12-31T10:01:23.436-0300] {processor.py:161} INFO - Started process (PID=33274) to work on /home/felipe/airflow/dags/05_query_with_dates.py
[2023-12-31T10:01:23.439-0300] {processor.py:830} INFO - Processing file /home/felipe/airflow/dags/05_query_with_dates.py for tasks to queue
[2023-12-31T10:01:23.447-0300] {logging_mixin.py:188} INFO - [2023-12-31T10:01:23.440-0300] {dagbag.py:538} INFO - Filling up the DagBag from /home/felipe/airflow/dags/05_query_with_dates.py
[2023-12-31T10:01:23.458-0300] {logging_mixin.py:188} INFO - [2023-12-31T10:01:23.457-0300] {dagbag.py:348} ERROR - Failed to import: /home/felipe/airflow/dags/05_query_with_dates.py
Traceback (most recent call last):
  File "/home/felipe/.local/lib/python3.10/site-packages/airflow/models/dagbag.py", line 344, in parse
    loader.exec_module(new_module)
  File "<frozen importlib._bootstrap_external>", line 883, in exec_module
  File "<frozen importlib._bootstrap>", line 241, in _call_with_frames_removed
  File "/home/felipe/airflow/dags/05_query_with_dates.py", line 4, in <module>
    import pandas as pd
ModuleNotFoundError: No module named 'pandas'
[2023-12-31T10:01:23.458-0300] {processor.py:842} WARNING - No viable dags retrieved from /home/felipe/airflow/dags/05_query_with_dates.py
[2023-12-31T10:01:23.648-0300] {processor.py:183} INFO - Processing /home/felipe/airflow/dags/05_query_with_dates.py took 0.229 seconds
[2023-12-31T10:02:32.077-0300] {processor.py:161} INFO - Started process (PID=33341) to work on /home/felipe/airflow/dags/05_query_with_dates.py
[2023-12-31T10:02:32.079-0300] {processor.py:830} INFO - Processing file /home/felipe/airflow/dags/05_query_with_dates.py for tasks to queue
[2023-12-31T10:02:32.088-0300] {logging_mixin.py:188} INFO - [2023-12-31T10:02:32.087-0300] {dagbag.py:538} INFO - Filling up the DagBag from /home/felipe/airflow/dags/05_query_with_dates.py
[2023-12-31T10:02:32.107-0300] {logging_mixin.py:188} INFO - [2023-12-31T10:02:32.099-0300] {dagbag.py:348} ERROR - Failed to import: /home/felipe/airflow/dags/05_query_with_dates.py
Traceback (most recent call last):
  File "/home/felipe/.local/lib/python3.10/site-packages/airflow/models/dagbag.py", line 344, in parse
    loader.exec_module(new_module)
  File "<frozen importlib._bootstrap_external>", line 883, in exec_module
  File "<frozen importlib._bootstrap>", line 241, in _call_with_frames_removed
  File "/home/felipe/airflow/dags/05_query_with_dates.py", line 4, in <module>
    import pandas as pd
ModuleNotFoundError: No module named 'pandas'
[2023-12-31T10:02:32.107-0300] {processor.py:842} WARNING - No viable dags retrieved from /home/felipe/airflow/dags/05_query_with_dates.py
[2023-12-31T10:02:32.209-0300] {processor.py:183} INFO - Processing /home/felipe/airflow/dags/05_query_with_dates.py took 0.143 seconds
[2023-12-31T10:03:36.997-0300] {processor.py:161} INFO - Started process (PID=33413) to work on /home/felipe/airflow/dags/05_query_with_dates.py
[2023-12-31T10:03:36.999-0300] {processor.py:830} INFO - Processing file /home/felipe/airflow/dags/05_query_with_dates.py for tasks to queue
[2023-12-31T10:03:37.008-0300] {logging_mixin.py:188} INFO - [2023-12-31T10:03:37.007-0300] {dagbag.py:538} INFO - Filling up the DagBag from /home/felipe/airflow/dags/05_query_with_dates.py
[2023-12-31T10:03:37.026-0300] {logging_mixin.py:188} INFO - [2023-12-31T10:03:37.019-0300] {dagbag.py:348} ERROR - Failed to import: /home/felipe/airflow/dags/05_query_with_dates.py
Traceback (most recent call last):
  File "/home/felipe/.local/lib/python3.10/site-packages/airflow/models/dagbag.py", line 344, in parse
    loader.exec_module(new_module)
  File "<frozen importlib._bootstrap_external>", line 883, in exec_module
  File "<frozen importlib._bootstrap>", line 241, in _call_with_frames_removed
  File "/home/felipe/airflow/dags/05_query_with_dates.py", line 4, in <module>
    import pandas as pd
ModuleNotFoundError: No module named 'pandas'
[2023-12-31T10:03:37.027-0300] {processor.py:842} WARNING - No viable dags retrieved from /home/felipe/airflow/dags/05_query_with_dates.py
[2023-12-31T10:03:37.119-0300] {processor.py:183} INFO - Processing /home/felipe/airflow/dags/05_query_with_dates.py took 0.139 seconds
[2023-12-31T10:04:48.927-0300] {processor.py:161} INFO - Started process (PID=33493) to work on /home/felipe/airflow/dags/05_query_with_dates.py
[2023-12-31T10:04:48.930-0300] {processor.py:830} INFO - Processing file /home/felipe/airflow/dags/05_query_with_dates.py for tasks to queue
[2023-12-31T10:04:48.938-0300] {logging_mixin.py:188} INFO - [2023-12-31T10:04:48.937-0300] {dagbag.py:538} INFO - Filling up the DagBag from /home/felipe/airflow/dags/05_query_with_dates.py
[2023-12-31T10:04:48.956-0300] {logging_mixin.py:188} INFO - [2023-12-31T10:04:48.949-0300] {dagbag.py:348} ERROR - Failed to import: /home/felipe/airflow/dags/05_query_with_dates.py
Traceback (most recent call last):
  File "/home/felipe/.local/lib/python3.10/site-packages/airflow/models/dagbag.py", line 344, in parse
    loader.exec_module(new_module)
  File "<frozen importlib._bootstrap_external>", line 883, in exec_module
  File "<frozen importlib._bootstrap>", line 241, in _call_with_frames_removed
  File "/home/felipe/airflow/dags/05_query_with_dates.py", line 4, in <module>
    import pandas as pd
ModuleNotFoundError: No module named 'pandas'
[2023-12-31T10:04:48.957-0300] {processor.py:842} WARNING - No viable dags retrieved from /home/felipe/airflow/dags/05_query_with_dates.py
[2023-12-31T10:04:49.058-0300] {processor.py:183} INFO - Processing /home/felipe/airflow/dags/05_query_with_dates.py took 0.141 seconds
[2023-12-31T10:06:00.189-0300] {processor.py:161} INFO - Started process (PID=33579) to work on /home/felipe/airflow/dags/05_query_with_dates.py
[2023-12-31T10:06:00.198-0300] {processor.py:830} INFO - Processing file /home/felipe/airflow/dags/05_query_with_dates.py for tasks to queue
[2023-12-31T10:06:00.206-0300] {logging_mixin.py:188} INFO - [2023-12-31T10:06:00.199-0300] {dagbag.py:538} INFO - Filling up the DagBag from /home/felipe/airflow/dags/05_query_with_dates.py
[2023-12-31T10:06:00.218-0300] {logging_mixin.py:188} INFO - [2023-12-31T10:06:00.217-0300] {dagbag.py:348} ERROR - Failed to import: /home/felipe/airflow/dags/05_query_with_dates.py
Traceback (most recent call last):
  File "/home/felipe/.local/lib/python3.10/site-packages/airflow/models/dagbag.py", line 344, in parse
    loader.exec_module(new_module)
  File "<frozen importlib._bootstrap_external>", line 883, in exec_module
  File "<frozen importlib._bootstrap>", line 241, in _call_with_frames_removed
  File "/home/felipe/airflow/dags/05_query_with_dates.py", line 4, in <module>
    import pandas as pd
ModuleNotFoundError: No module named 'pandas'
[2023-12-31T10:06:00.219-0300] {processor.py:842} WARNING - No viable dags retrieved from /home/felipe/airflow/dags/05_query_with_dates.py
[2023-12-31T10:06:00.339-0300] {processor.py:183} INFO - Processing /home/felipe/airflow/dags/05_query_with_dates.py took 0.160 seconds
[2023-12-31T10:07:11.228-0300] {processor.py:161} INFO - Started process (PID=33688) to work on /home/felipe/airflow/dags/05_query_with_dates.py
[2023-12-31T10:07:11.237-0300] {processor.py:830} INFO - Processing file /home/felipe/airflow/dags/05_query_with_dates.py for tasks to queue
[2023-12-31T10:07:11.238-0300] {logging_mixin.py:188} INFO - [2023-12-31T10:07:11.238-0300] {dagbag.py:538} INFO - Filling up the DagBag from /home/felipe/airflow/dags/05_query_with_dates.py
[2023-12-31T10:07:11.257-0300] {logging_mixin.py:188} INFO - [2023-12-31T10:07:11.249-0300] {dagbag.py:348} ERROR - Failed to import: /home/felipe/airflow/dags/05_query_with_dates.py
Traceback (most recent call last):
  File "/home/felipe/.local/lib/python3.10/site-packages/airflow/models/dagbag.py", line 344, in parse
    loader.exec_module(new_module)
  File "<frozen importlib._bootstrap_external>", line 883, in exec_module
  File "<frozen importlib._bootstrap>", line 241, in _call_with_frames_removed
  File "/home/felipe/airflow/dags/05_query_with_dates.py", line 4, in <module>
    import pandas as pd
ModuleNotFoundError: No module named 'pandas'
[2023-12-31T10:07:11.258-0300] {processor.py:842} WARNING - No viable dags retrieved from /home/felipe/airflow/dags/05_query_with_dates.py
[2023-12-31T10:07:11.388-0300] {processor.py:183} INFO - Processing /home/felipe/airflow/dags/05_query_with_dates.py took 0.170 seconds
[2023-12-31T10:08:23.958-0300] {processor.py:161} INFO - Started process (PID=33772) to work on /home/felipe/airflow/dags/05_query_with_dates.py
[2023-12-31T10:08:23.966-0300] {processor.py:830} INFO - Processing file /home/felipe/airflow/dags/05_query_with_dates.py for tasks to queue
[2023-12-31T10:08:23.968-0300] {logging_mixin.py:188} INFO - [2023-12-31T10:08:23.967-0300] {dagbag.py:538} INFO - Filling up the DagBag from /home/felipe/airflow/dags/05_query_with_dates.py
[2023-12-31T10:08:23.979-0300] {logging_mixin.py:188} INFO - [2023-12-31T10:08:23.978-0300] {dagbag.py:348} ERROR - Failed to import: /home/felipe/airflow/dags/05_query_with_dates.py
Traceback (most recent call last):
  File "/home/felipe/.local/lib/python3.10/site-packages/airflow/models/dagbag.py", line 344, in parse
    loader.exec_module(new_module)
  File "<frozen importlib._bootstrap_external>", line 883, in exec_module
  File "<frozen importlib._bootstrap>", line 241, in _call_with_frames_removed
  File "/home/felipe/airflow/dags/05_query_with_dates.py", line 4, in <module>
    import pandas as pd
ModuleNotFoundError: No module named 'pandas'
[2023-12-31T10:08:23.987-0300] {processor.py:842} WARNING - No viable dags retrieved from /home/felipe/airflow/dags/05_query_with_dates.py
[2023-12-31T10:08:24.087-0300] {processor.py:183} INFO - Processing /home/felipe/airflow/dags/05_query_with_dates.py took 0.159 seconds
[2023-12-31T11:28:55.556-0300] {processor.py:161} INFO - Started process (PID=33960) to work on /home/felipe/airflow/dags/05_query_with_dates.py
[2023-12-31T11:28:55.566-0300] {processor.py:830} INFO - Processing file /home/felipe/airflow/dags/05_query_with_dates.py for tasks to queue
[2023-12-31T11:28:55.577-0300] {logging_mixin.py:188} INFO - [2023-12-31T11:28:55.576-0300] {dagbag.py:538} INFO - Filling up the DagBag from /home/felipe/airflow/dags/05_query_with_dates.py
[2023-12-31T11:28:55.626-0300] {logging_mixin.py:188} INFO - [2023-12-31T11:28:55.615-0300] {dagbag.py:348} ERROR - Failed to import: /home/felipe/airflow/dags/05_query_with_dates.py
Traceback (most recent call last):
  File "/home/felipe/.local/lib/python3.10/site-packages/airflow/models/dagbag.py", line 344, in parse
    loader.exec_module(new_module)
  File "<frozen importlib._bootstrap_external>", line 883, in exec_module
  File "<frozen importlib._bootstrap>", line 241, in _call_with_frames_removed
  File "/home/felipe/airflow/dags/05_query_with_dates.py", line 4, in <module>
    import pandas as pd
ModuleNotFoundError: No module named 'pandas'
[2023-12-31T11:28:55.634-0300] {processor.py:842} WARNING - No viable dags retrieved from /home/felipe/airflow/dags/05_query_with_dates.py
[2023-12-31T11:28:56.066-0300] {processor.py:183} INFO - Processing /home/felipe/airflow/dags/05_query_with_dates.py took 0.541 seconds
[2023-12-31T11:30:49.497-0300] {processor.py:161} INFO - Started process (PID=34234) to work on /home/felipe/airflow/dags/05_query_with_dates.py
[2023-12-31T11:30:49.514-0300] {processor.py:830} INFO - Processing file /home/felipe/airflow/dags/05_query_with_dates.py for tasks to queue
[2023-12-31T11:30:49.516-0300] {logging_mixin.py:188} INFO - [2023-12-31T11:30:49.515-0300] {dagbag.py:538} INFO - Filling up the DagBag from /home/felipe/airflow/dags/05_query_with_dates.py
[2023-12-31T11:30:49.536-0300] {logging_mixin.py:188} INFO - [2023-12-31T11:30:49.535-0300] {dagbag.py:348} ERROR - Failed to import: /home/felipe/airflow/dags/05_query_with_dates.py
Traceback (most recent call last):
  File "/home/felipe/.local/lib/python3.10/site-packages/airflow/models/dagbag.py", line 344, in parse
    loader.exec_module(new_module)
  File "<frozen importlib._bootstrap_external>", line 883, in exec_module
  File "<frozen importlib._bootstrap>", line 241, in _call_with_frames_removed
  File "/home/felipe/airflow/dags/05_query_with_dates.py", line 4, in <module>
    import pandas as pd
ModuleNotFoundError: No module named 'pandas'
[2023-12-31T11:30:49.537-0300] {processor.py:842} WARNING - No viable dags retrieved from /home/felipe/airflow/dags/05_query_with_dates.py
[2023-12-31T11:30:49.665-0300] {processor.py:183} INFO - Processing /home/felipe/airflow/dags/05_query_with_dates.py took 0.181 seconds
[2023-12-31T11:32:20.626-0300] {processor.py:161} INFO - Started process (PID=34342) to work on /home/felipe/airflow/dags/05_query_with_dates.py
[2023-12-31T11:32:20.636-0300] {processor.py:830} INFO - Processing file /home/felipe/airflow/dags/05_query_with_dates.py for tasks to queue
[2023-12-31T11:32:20.644-0300] {logging_mixin.py:188} INFO - [2023-12-31T11:32:20.644-0300] {dagbag.py:538} INFO - Filling up the DagBag from /home/felipe/airflow/dags/05_query_with_dates.py
[2023-12-31T11:32:20.664-0300] {logging_mixin.py:188} INFO - [2023-12-31T11:32:20.656-0300] {dagbag.py:348} ERROR - Failed to import: /home/felipe/airflow/dags/05_query_with_dates.py
Traceback (most recent call last):
  File "/home/felipe/.local/lib/python3.10/site-packages/airflow/models/dagbag.py", line 344, in parse
    loader.exec_module(new_module)
  File "<frozen importlib._bootstrap_external>", line 883, in exec_module
  File "<frozen importlib._bootstrap>", line 241, in _call_with_frames_removed
  File "/home/felipe/airflow/dags/05_query_with_dates.py", line 4, in <module>
    import pandas as pd
ModuleNotFoundError: No module named 'pandas'
[2023-12-31T11:32:20.665-0300] {processor.py:842} WARNING - No viable dags retrieved from /home/felipe/airflow/dags/05_query_with_dates.py
[2023-12-31T11:32:20.787-0300] {processor.py:183} INFO - Processing /home/felipe/airflow/dags/05_query_with_dates.py took 0.171 seconds
[2023-12-31T11:33:51.604-0300] {processor.py:161} INFO - Started process (PID=34438) to work on /home/felipe/airflow/dags/05_query_with_dates.py
[2023-12-31T11:33:51.615-0300] {processor.py:830} INFO - Processing file /home/felipe/airflow/dags/05_query_with_dates.py for tasks to queue
[2023-12-31T11:33:51.624-0300] {logging_mixin.py:188} INFO - [2023-12-31T11:33:51.616-0300] {dagbag.py:538} INFO - Filling up the DagBag from /home/felipe/airflow/dags/05_query_with_dates.py
[2023-12-31T11:33:51.646-0300] {logging_mixin.py:188} INFO - [2023-12-31T11:33:51.645-0300] {dagbag.py:348} ERROR - Failed to import: /home/felipe/airflow/dags/05_query_with_dates.py
Traceback (most recent call last):
  File "/home/felipe/.local/lib/python3.10/site-packages/airflow/models/dagbag.py", line 344, in parse
    loader.exec_module(new_module)
  File "<frozen importlib._bootstrap_external>", line 883, in exec_module
  File "<frozen importlib._bootstrap>", line 241, in _call_with_frames_removed
  File "/home/felipe/airflow/dags/05_query_with_dates.py", line 4, in <module>
    import pandas as pd
ModuleNotFoundError: No module named 'pandas'
[2023-12-31T11:33:51.655-0300] {processor.py:842} WARNING - No viable dags retrieved from /home/felipe/airflow/dags/05_query_with_dates.py
[2023-12-31T11:33:51.776-0300] {processor.py:183} INFO - Processing /home/felipe/airflow/dags/05_query_with_dates.py took 0.201 seconds
[2023-12-31T11:35:13.346-0300] {processor.py:161} INFO - Started process (PID=34562) to work on /home/felipe/airflow/dags/05_query_with_dates.py
[2023-12-31T11:35:13.354-0300] {processor.py:830} INFO - Processing file /home/felipe/airflow/dags/05_query_with_dates.py for tasks to queue
[2023-12-31T11:35:13.356-0300] {logging_mixin.py:188} INFO - [2023-12-31T11:35:13.355-0300] {dagbag.py:538} INFO - Filling up the DagBag from /home/felipe/airflow/dags/05_query_with_dates.py
[2023-12-31T11:35:13.375-0300] {logging_mixin.py:188} INFO - [2023-12-31T11:35:13.374-0300] {dagbag.py:348} ERROR - Failed to import: /home/felipe/airflow/dags/05_query_with_dates.py
Traceback (most recent call last):
  File "/home/felipe/.local/lib/python3.10/site-packages/airflow/models/dagbag.py", line 344, in parse
    loader.exec_module(new_module)
  File "<frozen importlib._bootstrap_external>", line 883, in exec_module
  File "<frozen importlib._bootstrap>", line 241, in _call_with_frames_removed
  File "/home/felipe/airflow/dags/05_query_with_dates.py", line 4, in <module>
    import pandas as pd
ModuleNotFoundError: No module named 'pandas'
[2023-12-31T11:35:13.376-0300] {processor.py:842} WARNING - No viable dags retrieved from /home/felipe/airflow/dags/05_query_with_dates.py
[2023-12-31T11:35:13.487-0300] {processor.py:183} INFO - Processing /home/felipe/airflow/dags/05_query_with_dates.py took 0.152 seconds
[2023-12-31T11:36:36.556-0300] {processor.py:161} INFO - Started process (PID=34651) to work on /home/felipe/airflow/dags/05_query_with_dates.py
[2023-12-31T11:36:36.574-0300] {processor.py:830} INFO - Processing file /home/felipe/airflow/dags/05_query_with_dates.py for tasks to queue
[2023-12-31T11:36:36.576-0300] {logging_mixin.py:188} INFO - [2023-12-31T11:36:36.575-0300] {dagbag.py:538} INFO - Filling up the DagBag from /home/felipe/airflow/dags/05_query_with_dates.py
[2023-12-31T11:36:36.595-0300] {logging_mixin.py:188} INFO - [2023-12-31T11:36:36.594-0300] {dagbag.py:348} ERROR - Failed to import: /home/felipe/airflow/dags/05_query_with_dates.py
Traceback (most recent call last):
  File "/home/felipe/.local/lib/python3.10/site-packages/airflow/models/dagbag.py", line 344, in parse
    loader.exec_module(new_module)
  File "<frozen importlib._bootstrap_external>", line 883, in exec_module
  File "<frozen importlib._bootstrap>", line 241, in _call_with_frames_removed
  File "/home/felipe/airflow/dags/05_query_with_dates.py", line 4, in <module>
    import pandas as pd
ModuleNotFoundError: No module named 'pandas'
[2023-12-31T11:36:36.596-0300] {processor.py:842} WARNING - No viable dags retrieved from /home/felipe/airflow/dags/05_query_with_dates.py
[2023-12-31T11:36:36.715-0300] {processor.py:183} INFO - Processing /home/felipe/airflow/dags/05_query_with_dates.py took 0.170 seconds
[2023-12-31T11:38:00.466-0300] {processor.py:161} INFO - Started process (PID=34738) to work on /home/felipe/airflow/dags/05_query_with_dates.py
[2023-12-31T11:38:00.476-0300] {processor.py:830} INFO - Processing file /home/felipe/airflow/dags/05_query_with_dates.py for tasks to queue
[2023-12-31T11:38:00.485-0300] {logging_mixin.py:188} INFO - [2023-12-31T11:38:00.484-0300] {dagbag.py:538} INFO - Filling up the DagBag from /home/felipe/airflow/dags/05_query_with_dates.py
[2023-12-31T11:38:00.504-0300] {logging_mixin.py:188} INFO - [2023-12-31T11:38:00.496-0300] {dagbag.py:348} ERROR - Failed to import: /home/felipe/airflow/dags/05_query_with_dates.py
Traceback (most recent call last):
  File "/home/felipe/.local/lib/python3.10/site-packages/airflow/models/dagbag.py", line 344, in parse
    loader.exec_module(new_module)
  File "<frozen importlib._bootstrap_external>", line 883, in exec_module
  File "<frozen importlib._bootstrap>", line 241, in _call_with_frames_removed
  File "/home/felipe/airflow/dags/05_query_with_dates.py", line 4, in <module>
    import pandas as pd
ModuleNotFoundError: No module named 'pandas'
[2023-12-31T11:38:00.506-0300] {processor.py:842} WARNING - No viable dags retrieved from /home/felipe/airflow/dags/05_query_with_dates.py
[2023-12-31T11:38:00.655-0300] {processor.py:183} INFO - Processing /home/felipe/airflow/dags/05_query_with_dates.py took 0.200 seconds
[2023-12-31T11:39:23.154-0300] {processor.py:161} INFO - Started process (PID=34833) to work on /home/felipe/airflow/dags/05_query_with_dates.py
[2023-12-31T11:39:23.176-0300] {processor.py:830} INFO - Processing file /home/felipe/airflow/dags/05_query_with_dates.py for tasks to queue
[2023-12-31T11:39:23.185-0300] {logging_mixin.py:188} INFO - [2023-12-31T11:39:23.184-0300] {dagbag.py:538} INFO - Filling up the DagBag from /home/felipe/airflow/dags/05_query_with_dates.py
[2023-12-31T11:39:23.205-0300] {logging_mixin.py:188} INFO - [2023-12-31T11:39:23.196-0300] {dagbag.py:348} ERROR - Failed to import: /home/felipe/airflow/dags/05_query_with_dates.py
Traceback (most recent call last):
  File "/home/felipe/.local/lib/python3.10/site-packages/airflow/models/dagbag.py", line 344, in parse
    loader.exec_module(new_module)
  File "<frozen importlib._bootstrap_external>", line 883, in exec_module
  File "<frozen importlib._bootstrap>", line 241, in _call_with_frames_removed
  File "/home/felipe/airflow/dags/05_query_with_dates.py", line 4, in <module>
    import pandas as pd
ModuleNotFoundError: No module named 'pandas'
[2023-12-31T11:39:23.206-0300] {processor.py:842} WARNING - No viable dags retrieved from /home/felipe/airflow/dags/05_query_with_dates.py
[2023-12-31T11:39:23.345-0300] {processor.py:183} INFO - Processing /home/felipe/airflow/dags/05_query_with_dates.py took 0.220 seconds
[2023-12-31T11:40:45.576-0300] {processor.py:161} INFO - Started process (PID=34949) to work on /home/felipe/airflow/dags/05_query_with_dates.py
[2023-12-31T11:40:45.585-0300] {processor.py:830} INFO - Processing file /home/felipe/airflow/dags/05_query_with_dates.py for tasks to queue
[2023-12-31T11:40:45.594-0300] {logging_mixin.py:188} INFO - [2023-12-31T11:40:45.586-0300] {dagbag.py:538} INFO - Filling up the DagBag from /home/felipe/airflow/dags/05_query_with_dates.py
[2023-12-31T11:40:45.614-0300] {logging_mixin.py:188} INFO - [2023-12-31T11:40:45.606-0300] {dagbag.py:348} ERROR - Failed to import: /home/felipe/airflow/dags/05_query_with_dates.py
Traceback (most recent call last):
  File "/home/felipe/.local/lib/python3.10/site-packages/airflow/models/dagbag.py", line 344, in parse
    loader.exec_module(new_module)
  File "<frozen importlib._bootstrap_external>", line 883, in exec_module
  File "<frozen importlib._bootstrap>", line 241, in _call_with_frames_removed
  File "/home/felipe/airflow/dags/05_query_with_dates.py", line 4, in <module>
    import pandas as pd
ModuleNotFoundError: No module named 'pandas'
[2023-12-31T11:40:45.615-0300] {processor.py:842} WARNING - No viable dags retrieved from /home/felipe/airflow/dags/05_query_with_dates.py
[2023-12-31T11:40:45.765-0300] {processor.py:183} INFO - Processing /home/felipe/airflow/dags/05_query_with_dates.py took 0.201 seconds
[2023-12-31T11:42:19.285-0300] {processor.py:161} INFO - Started process (PID=35055) to work on /home/felipe/airflow/dags/05_query_with_dates.py
[2023-12-31T11:42:19.295-0300] {processor.py:830} INFO - Processing file /home/felipe/airflow/dags/05_query_with_dates.py for tasks to queue
[2023-12-31T11:42:19.305-0300] {logging_mixin.py:188} INFO - [2023-12-31T11:42:19.296-0300] {dagbag.py:538} INFO - Filling up the DagBag from /home/felipe/airflow/dags/05_query_with_dates.py
[2023-12-31T11:42:19.345-0300] {logging_mixin.py:188} INFO - [2023-12-31T11:42:19.326-0300] {dagbag.py:348} ERROR - Failed to import: /home/felipe/airflow/dags/05_query_with_dates.py
Traceback (most recent call last):
  File "/home/felipe/.local/lib/python3.10/site-packages/airflow/models/dagbag.py", line 344, in parse
    loader.exec_module(new_module)
  File "<frozen importlib._bootstrap_external>", line 883, in exec_module
  File "<frozen importlib._bootstrap>", line 241, in _call_with_frames_removed
  File "/home/felipe/airflow/dags/05_query_with_dates.py", line 4, in <module>
    import pandas as pd
ModuleNotFoundError: No module named 'pandas'
[2023-12-31T11:42:19.346-0300] {processor.py:842} WARNING - No viable dags retrieved from /home/felipe/airflow/dags/05_query_with_dates.py
[2023-12-31T11:42:19.576-0300] {processor.py:183} INFO - Processing /home/felipe/airflow/dags/05_query_with_dates.py took 0.312 seconds
[2023-12-31T11:43:55.734-0300] {processor.py:161} INFO - Started process (PID=35165) to work on /home/felipe/airflow/dags/05_query_with_dates.py
[2023-12-31T11:43:55.736-0300] {processor.py:830} INFO - Processing file /home/felipe/airflow/dags/05_query_with_dates.py for tasks to queue
[2023-12-31T11:43:55.746-0300] {logging_mixin.py:188} INFO - [2023-12-31T11:43:55.745-0300] {dagbag.py:538} INFO - Filling up the DagBag from /home/felipe/airflow/dags/05_query_with_dates.py
[2023-12-31T11:43:55.775-0300] {logging_mixin.py:188} INFO - [2023-12-31T11:43:55.774-0300] {dagbag.py:348} ERROR - Failed to import: /home/felipe/airflow/dags/05_query_with_dates.py
Traceback (most recent call last):
  File "/home/felipe/.local/lib/python3.10/site-packages/airflow/models/dagbag.py", line 344, in parse
    loader.exec_module(new_module)
  File "<frozen importlib._bootstrap_external>", line 883, in exec_module
  File "<frozen importlib._bootstrap>", line 241, in _call_with_frames_removed
  File "/home/felipe/airflow/dags/05_query_with_dates.py", line 4, in <module>
    import pandas as pd
ModuleNotFoundError: No module named 'pandas'
[2023-12-31T11:43:55.784-0300] {processor.py:842} WARNING - No viable dags retrieved from /home/felipe/airflow/dags/05_query_with_dates.py
[2023-12-31T11:43:56.014-0300] {processor.py:183} INFO - Processing /home/felipe/airflow/dags/05_query_with_dates.py took 0.300 seconds
[2023-12-31T11:45:36.855-0300] {processor.py:161} INFO - Started process (PID=35304) to work on /home/felipe/airflow/dags/05_query_with_dates.py
[2023-12-31T11:45:36.864-0300] {processor.py:830} INFO - Processing file /home/felipe/airflow/dags/05_query_with_dates.py for tasks to queue
[2023-12-31T11:45:36.866-0300] {logging_mixin.py:188} INFO - [2023-12-31T11:45:36.865-0300] {dagbag.py:538} INFO - Filling up the DagBag from /home/felipe/airflow/dags/05_query_with_dates.py
[2023-12-31T11:45:36.886-0300] {logging_mixin.py:188} INFO - [2023-12-31T11:45:36.884-0300] {dagbag.py:348} ERROR - Failed to import: /home/felipe/airflow/dags/05_query_with_dates.py
Traceback (most recent call last):
  File "/home/felipe/.local/lib/python3.10/site-packages/airflow/models/dagbag.py", line 344, in parse
    loader.exec_module(new_module)
  File "<frozen importlib._bootstrap_external>", line 883, in exec_module
  File "<frozen importlib._bootstrap>", line 241, in _call_with_frames_removed
  File "/home/felipe/airflow/dags/05_query_with_dates.py", line 4, in <module>
    import pandas as pd
ModuleNotFoundError: No module named 'pandas'
[2023-12-31T11:45:36.894-0300] {processor.py:842} WARNING - No viable dags retrieved from /home/felipe/airflow/dags/05_query_with_dates.py
[2023-12-31T11:45:37.035-0300] {processor.py:183} INFO - Processing /home/felipe/airflow/dags/05_query_with_dates.py took 0.199 seconds
[2023-12-31T11:47:14.506-0300] {processor.py:161} INFO - Started process (PID=35428) to work on /home/felipe/airflow/dags/05_query_with_dates.py
[2023-12-31T11:47:14.524-0300] {processor.py:830} INFO - Processing file /home/felipe/airflow/dags/05_query_with_dates.py for tasks to queue
[2023-12-31T11:47:14.525-0300] {logging_mixin.py:188} INFO - [2023-12-31T11:47:14.525-0300] {dagbag.py:538} INFO - Filling up the DagBag from /home/felipe/airflow/dags/05_query_with_dates.py
[2023-12-31T11:47:14.546-0300] {logging_mixin.py:188} INFO - [2023-12-31T11:47:14.544-0300] {dagbag.py:348} ERROR - Failed to import: /home/felipe/airflow/dags/05_query_with_dates.py
Traceback (most recent call last):
  File "/home/felipe/.local/lib/python3.10/site-packages/airflow/models/dagbag.py", line 344, in parse
    loader.exec_module(new_module)
  File "<frozen importlib._bootstrap_external>", line 883, in exec_module
  File "<frozen importlib._bootstrap>", line 241, in _call_with_frames_removed
  File "/home/felipe/airflow/dags/05_query_with_dates.py", line 4, in <module>
    import pandas as pd
ModuleNotFoundError: No module named 'pandas'
[2023-12-31T11:47:14.554-0300] {processor.py:842} WARNING - No viable dags retrieved from /home/felipe/airflow/dags/05_query_with_dates.py
[2023-12-31T11:47:14.726-0300] {processor.py:183} INFO - Processing /home/felipe/airflow/dags/05_query_with_dates.py took 0.241 seconds
[2023-12-31T11:49:27.045-0300] {processor.py:161} INFO - Started process (PID=35587) to work on /home/felipe/airflow/dags/05_query_with_dates.py
[2023-12-31T11:49:27.056-0300] {processor.py:830} INFO - Processing file /home/felipe/airflow/dags/05_query_with_dates.py for tasks to queue
[2023-12-31T11:49:27.065-0300] {logging_mixin.py:188} INFO - [2023-12-31T11:49:27.064-0300] {dagbag.py:538} INFO - Filling up the DagBag from /home/felipe/airflow/dags/05_query_with_dates.py
[2023-12-31T11:49:27.114-0300] {logging_mixin.py:188} INFO - [2023-12-31T11:49:27.096-0300] {dagbag.py:348} ERROR - Failed to import: /home/felipe/airflow/dags/05_query_with_dates.py
Traceback (most recent call last):
  File "/home/felipe/.local/lib/python3.10/site-packages/airflow/models/dagbag.py", line 344, in parse
    loader.exec_module(new_module)
  File "<frozen importlib._bootstrap_external>", line 883, in exec_module
  File "<frozen importlib._bootstrap>", line 241, in _call_with_frames_removed
  File "/home/felipe/airflow/dags/05_query_with_dates.py", line 4, in <module>
    import pandas as pd
ModuleNotFoundError: No module named 'pandas'
[2023-12-31T11:49:27.115-0300] {processor.py:842} WARNING - No viable dags retrieved from /home/felipe/airflow/dags/05_query_with_dates.py
[2023-12-31T11:49:27.335-0300] {processor.py:183} INFO - Processing /home/felipe/airflow/dags/05_query_with_dates.py took 0.319 seconds
[2023-12-31T11:51:36.936-0300] {processor.py:161} INFO - Started process (PID=35738) to work on /home/felipe/airflow/dags/05_query_with_dates.py
[2023-12-31T11:51:36.955-0300] {processor.py:830} INFO - Processing file /home/felipe/airflow/dags/05_query_with_dates.py for tasks to queue
[2023-12-31T11:51:36.966-0300] {logging_mixin.py:188} INFO - [2023-12-31T11:51:36.965-0300] {dagbag.py:538} INFO - Filling up the DagBag from /home/felipe/airflow/dags/05_query_with_dates.py
[2023-12-31T11:51:37.024-0300] {logging_mixin.py:188} INFO - [2023-12-31T11:51:37.004-0300] {dagbag.py:348} ERROR - Failed to import: /home/felipe/airflow/dags/05_query_with_dates.py
Traceback (most recent call last):
  File "/home/felipe/.local/lib/python3.10/site-packages/airflow/models/dagbag.py", line 344, in parse
    loader.exec_module(new_module)
  File "<frozen importlib._bootstrap_external>", line 883, in exec_module
  File "<frozen importlib._bootstrap>", line 241, in _call_with_frames_removed
  File "/home/felipe/airflow/dags/05_query_with_dates.py", line 4, in <module>
    import pandas as pd
ModuleNotFoundError: No module named 'pandas'
[2023-12-31T11:51:37.025-0300] {processor.py:842} WARNING - No viable dags retrieved from /home/felipe/airflow/dags/05_query_with_dates.py
[2023-12-31T11:51:37.244-0300] {processor.py:183} INFO - Processing /home/felipe/airflow/dags/05_query_with_dates.py took 0.339 seconds
[2023-12-31T11:54:21.196-0300] {processor.py:161} INFO - Started process (PID=35871) to work on /home/felipe/airflow/dags/05_query_with_dates.py
[2023-12-31T11:54:21.214-0300] {processor.py:830} INFO - Processing file /home/felipe/airflow/dags/05_query_with_dates.py for tasks to queue
[2023-12-31T11:54:21.215-0300] {logging_mixin.py:188} INFO - [2023-12-31T11:54:21.215-0300] {dagbag.py:538} INFO - Filling up the DagBag from /home/felipe/airflow/dags/05_query_with_dates.py
[2023-12-31T11:54:21.244-0300] {logging_mixin.py:188} INFO - [2023-12-31T11:54:21.235-0300] {dagbag.py:348} ERROR - Failed to import: /home/felipe/airflow/dags/05_query_with_dates.py
Traceback (most recent call last):
  File "/home/felipe/.local/lib/python3.10/site-packages/airflow/models/dagbag.py", line 344, in parse
    loader.exec_module(new_module)
  File "<frozen importlib._bootstrap_external>", line 883, in exec_module
  File "<frozen importlib._bootstrap>", line 241, in _call_with_frames_removed
  File "/home/felipe/airflow/dags/05_query_with_dates.py", line 4, in <module>
    import pandas as pd
ModuleNotFoundError: No module named 'pandas'
[2023-12-31T11:54:21.244-0300] {processor.py:842} WARNING - No viable dags retrieved from /home/felipe/airflow/dags/05_query_with_dates.py
[2023-12-31T11:54:21.466-0300] {processor.py:183} INFO - Processing /home/felipe/airflow/dags/05_query_with_dates.py took 0.291 seconds
[2023-12-31T11:56:14.035-0300] {processor.py:161} INFO - Started process (PID=36006) to work on /home/felipe/airflow/dags/05_query_with_dates.py
[2023-12-31T11:56:14.045-0300] {processor.py:830} INFO - Processing file /home/felipe/airflow/dags/05_query_with_dates.py for tasks to queue
[2023-12-31T11:56:14.055-0300] {logging_mixin.py:188} INFO - [2023-12-31T11:56:14.054-0300] {dagbag.py:538} INFO - Filling up the DagBag from /home/felipe/airflow/dags/05_query_with_dates.py
[2023-12-31T11:56:14.085-0300] {logging_mixin.py:188} INFO - [2023-12-31T11:56:14.074-0300] {dagbag.py:348} ERROR - Failed to import: /home/felipe/airflow/dags/05_query_with_dates.py
Traceback (most recent call last):
  File "/home/felipe/.local/lib/python3.10/site-packages/airflow/models/dagbag.py", line 344, in parse
    loader.exec_module(new_module)
  File "<frozen importlib._bootstrap_external>", line 883, in exec_module
  File "<frozen importlib._bootstrap>", line 241, in _call_with_frames_removed
  File "/home/felipe/airflow/dags/05_query_with_dates.py", line 4, in <module>
    import pandas as pd
ModuleNotFoundError: No module named 'pandas'
[2023-12-31T11:56:14.085-0300] {processor.py:842} WARNING - No viable dags retrieved from /home/felipe/airflow/dags/05_query_with_dates.py
[2023-12-31T11:56:14.244-0300] {processor.py:183} INFO - Processing /home/felipe/airflow/dags/05_query_with_dates.py took 0.229 seconds
[2023-12-31T11:57:58.014-0300] {processor.py:161} INFO - Started process (PID=36111) to work on /home/felipe/airflow/dags/05_query_with_dates.py
[2023-12-31T11:57:58.024-0300] {processor.py:830} INFO - Processing file /home/felipe/airflow/dags/05_query_with_dates.py for tasks to queue
[2023-12-31T11:57:58.026-0300] {logging_mixin.py:188} INFO - [2023-12-31T11:57:58.025-0300] {dagbag.py:538} INFO - Filling up the DagBag from /home/felipe/airflow/dags/05_query_with_dates.py
[2023-12-31T11:57:58.054-0300] {logging_mixin.py:188} INFO - [2023-12-31T11:57:58.045-0300] {dagbag.py:348} ERROR - Failed to import: /home/felipe/airflow/dags/05_query_with_dates.py
Traceback (most recent call last):
  File "/home/felipe/.local/lib/python3.10/site-packages/airflow/models/dagbag.py", line 344, in parse
    loader.exec_module(new_module)
  File "<frozen importlib._bootstrap_external>", line 883, in exec_module
  File "<frozen importlib._bootstrap>", line 241, in _call_with_frames_removed
  File "/home/felipe/airflow/dags/05_query_with_dates.py", line 4, in <module>
    import pandas as pd
ModuleNotFoundError: No module named 'pandas'
[2023-12-31T11:57:58.055-0300] {processor.py:842} WARNING - No viable dags retrieved from /home/felipe/airflow/dags/05_query_with_dates.py
[2023-12-31T11:57:58.244-0300] {processor.py:183} INFO - Processing /home/felipe/airflow/dags/05_query_with_dates.py took 0.259 seconds
[2023-12-31T11:59:44.665-0300] {processor.py:161} INFO - Started process (PID=36216) to work on /home/felipe/airflow/dags/05_query_with_dates.py
[2023-12-31T11:59:44.675-0300] {processor.py:830} INFO - Processing file /home/felipe/airflow/dags/05_query_with_dates.py for tasks to queue
[2023-12-31T11:59:44.685-0300] {logging_mixin.py:188} INFO - [2023-12-31T11:59:44.684-0300] {dagbag.py:538} INFO - Filling up the DagBag from /home/felipe/airflow/dags/05_query_with_dates.py
[2023-12-31T11:59:44.715-0300] {logging_mixin.py:188} INFO - [2023-12-31T11:59:44.714-0300] {dagbag.py:348} ERROR - Failed to import: /home/felipe/airflow/dags/05_query_with_dates.py
Traceback (most recent call last):
  File "/home/felipe/.local/lib/python3.10/site-packages/airflow/models/dagbag.py", line 344, in parse
    loader.exec_module(new_module)
  File "<frozen importlib._bootstrap_external>", line 883, in exec_module
  File "<frozen importlib._bootstrap>", line 241, in _call_with_frames_removed
  File "/home/felipe/airflow/dags/05_query_with_dates.py", line 4, in <module>
    import pandas as pd
ModuleNotFoundError: No module named 'pandas'
[2023-12-31T11:59:44.724-0300] {processor.py:842} WARNING - No viable dags retrieved from /home/felipe/airflow/dags/05_query_with_dates.py
[2023-12-31T11:59:44.924-0300] {processor.py:183} INFO - Processing /home/felipe/airflow/dags/05_query_with_dates.py took 0.279 seconds
[2023-12-31T12:01:34.065-0300] {processor.py:161} INFO - Started process (PID=36348) to work on /home/felipe/airflow/dags/05_query_with_dates.py
[2023-12-31T12:01:34.075-0300] {processor.py:830} INFO - Processing file /home/felipe/airflow/dags/05_query_with_dates.py for tasks to queue
[2023-12-31T12:01:34.085-0300] {logging_mixin.py:188} INFO - [2023-12-31T12:01:34.084-0300] {dagbag.py:538} INFO - Filling up the DagBag from /home/felipe/airflow/dags/05_query_with_dates.py
[2023-12-31T12:01:34.115-0300] {logging_mixin.py:188} INFO - [2023-12-31T12:01:34.105-0300] {dagbag.py:348} ERROR - Failed to import: /home/felipe/airflow/dags/05_query_with_dates.py
Traceback (most recent call last):
  File "/home/felipe/.local/lib/python3.10/site-packages/airflow/models/dagbag.py", line 344, in parse
    loader.exec_module(new_module)
  File "<frozen importlib._bootstrap_external>", line 883, in exec_module
  File "<frozen importlib._bootstrap>", line 241, in _call_with_frames_removed
  File "/home/felipe/airflow/dags/05_query_with_dates.py", line 4, in <module>
    import pandas as pd
ModuleNotFoundError: No module named 'pandas'
[2023-12-31T12:01:34.124-0300] {processor.py:842} WARNING - No viable dags retrieved from /home/felipe/airflow/dags/05_query_with_dates.py
[2023-12-31T12:01:34.334-0300] {processor.py:183} INFO - Processing /home/felipe/airflow/dags/05_query_with_dates.py took 0.282 seconds
[2023-12-31T12:03:33.135-0300] {processor.py:161} INFO - Started process (PID=36455) to work on /home/felipe/airflow/dags/05_query_with_dates.py
[2023-12-31T12:03:33.154-0300] {processor.py:830} INFO - Processing file /home/felipe/airflow/dags/05_query_with_dates.py for tasks to queue
[2023-12-31T12:03:33.164-0300] {logging_mixin.py:188} INFO - [2023-12-31T12:03:33.155-0300] {dagbag.py:538} INFO - Filling up the DagBag from /home/felipe/airflow/dags/05_query_with_dates.py
[2023-12-31T12:03:33.204-0300] {logging_mixin.py:188} INFO - [2023-12-31T12:03:33.194-0300] {dagbag.py:348} ERROR - Failed to import: /home/felipe/airflow/dags/05_query_with_dates.py
Traceback (most recent call last):
  File "/home/felipe/.local/lib/python3.10/site-packages/airflow/models/dagbag.py", line 344, in parse
    loader.exec_module(new_module)
  File "<frozen importlib._bootstrap_external>", line 883, in exec_module
  File "<frozen importlib._bootstrap>", line 241, in _call_with_frames_removed
  File "/home/felipe/airflow/dags/05_query_with_dates.py", line 4, in <module>
    import pandas as pd
ModuleNotFoundError: No module named 'pandas'
[2023-12-31T12:03:33.214-0300] {processor.py:842} WARNING - No viable dags retrieved from /home/felipe/airflow/dags/05_query_with_dates.py
[2023-12-31T12:03:33.565-0300] {processor.py:183} INFO - Processing /home/felipe/airflow/dags/05_query_with_dates.py took 0.460 seconds
[2023-12-31T12:06:56.894-0300] {processor.py:161} INFO - Started process (PID=36714) to work on /home/felipe/airflow/dags/05_query_with_dates.py
[2023-12-31T12:06:56.915-0300] {processor.py:830} INFO - Processing file /home/felipe/airflow/dags/05_query_with_dates.py for tasks to queue
[2023-12-31T12:06:56.945-0300] {logging_mixin.py:188} INFO - [2023-12-31T12:06:56.935-0300] {dagbag.py:538} INFO - Filling up the DagBag from /home/felipe/airflow/dags/05_query_with_dates.py
[2023-12-31T12:06:57.005-0300] {logging_mixin.py:188} INFO - [2023-12-31T12:06:56.985-0300] {dagbag.py:348} ERROR - Failed to import: /home/felipe/airflow/dags/05_query_with_dates.py
Traceback (most recent call last):
  File "/home/felipe/.local/lib/python3.10/site-packages/airflow/models/dagbag.py", line 344, in parse
    loader.exec_module(new_module)
  File "<frozen importlib._bootstrap_external>", line 883, in exec_module
  File "<frozen importlib._bootstrap>", line 241, in _call_with_frames_removed
  File "/home/felipe/airflow/dags/05_query_with_dates.py", line 4, in <module>
    import pandas as pd
ModuleNotFoundError: No module named 'pandas'
[2023-12-31T12:06:57.015-0300] {processor.py:842} WARNING - No viable dags retrieved from /home/felipe/airflow/dags/05_query_with_dates.py
[2023-12-31T12:06:57.524-0300] {processor.py:183} INFO - Processing /home/felipe/airflow/dags/05_query_with_dates.py took 0.700 seconds
[2023-12-31T12:10:28.475-0300] {processor.py:161} INFO - Started process (PID=37099) to work on /home/felipe/airflow/dags/05_query_with_dates.py
[2023-12-31T12:10:28.494-0300] {processor.py:830} INFO - Processing file /home/felipe/airflow/dags/05_query_with_dates.py for tasks to queue
[2023-12-31T12:10:28.514-0300] {logging_mixin.py:188} INFO - [2023-12-31T12:10:28.505-0300] {dagbag.py:538} INFO - Filling up the DagBag from /home/felipe/airflow/dags/05_query_with_dates.py
[2023-12-31T12:10:28.584-0300] {logging_mixin.py:188} INFO - [2023-12-31T12:10:28.564-0300] {dagbag.py:348} ERROR - Failed to import: /home/felipe/airflow/dags/05_query_with_dates.py
Traceback (most recent call last):
  File "/home/felipe/.local/lib/python3.10/site-packages/airflow/models/dagbag.py", line 344, in parse
    loader.exec_module(new_module)
  File "<frozen importlib._bootstrap_external>", line 883, in exec_module
  File "<frozen importlib._bootstrap>", line 241, in _call_with_frames_removed
  File "/home/felipe/airflow/dags/05_query_with_dates.py", line 4, in <module>
    import pandas as pd
ModuleNotFoundError: No module named 'pandas'
[2023-12-31T12:10:28.594-0300] {processor.py:842} WARNING - No viable dags retrieved from /home/felipe/airflow/dags/05_query_with_dates.py
[2023-12-31T12:10:30.715-0300] {processor.py:183} INFO - Processing /home/felipe/airflow/dags/05_query_with_dates.py took 2.300 seconds
[2023-12-31T12:11:46.304-0300] {processor.py:161} INFO - Started process (PID=37203) to work on /home/felipe/airflow/dags/05_query_with_dates.py
[2023-12-31T12:11:46.314-0300] {processor.py:830} INFO - Processing file /home/felipe/airflow/dags/05_query_with_dates.py for tasks to queue
[2023-12-31T12:11:46.325-0300] {logging_mixin.py:188} INFO - [2023-12-31T12:11:46.324-0300] {dagbag.py:538} INFO - Filling up the DagBag from /home/felipe/airflow/dags/05_query_with_dates.py
[2023-12-31T12:11:46.374-0300] {logging_mixin.py:188} INFO - [2023-12-31T12:11:46.355-0300] {dagbag.py:348} ERROR - Failed to import: /home/felipe/airflow/dags/05_query_with_dates.py
Traceback (most recent call last):
  File "/home/felipe/.local/lib/python3.10/site-packages/airflow/models/dagbag.py", line 344, in parse
    loader.exec_module(new_module)
  File "<frozen importlib._bootstrap_external>", line 883, in exec_module
  File "<frozen importlib._bootstrap>", line 241, in _call_with_frames_removed
  File "/home/felipe/airflow/dags/05_query_with_dates.py", line 4, in <module>
    import pandas as pd
ModuleNotFoundError: No module named 'pandas'
[2023-12-31T12:11:46.375-0300] {processor.py:842} WARNING - No viable dags retrieved from /home/felipe/airflow/dags/05_query_with_dates.py
[2023-12-31T12:11:46.634-0300] {processor.py:183} INFO - Processing /home/felipe/airflow/dags/05_query_with_dates.py took 0.360 seconds
[2023-12-31T12:12:35.815-0300] {processor.py:161} INFO - Started process (PID=37270) to work on /home/felipe/airflow/dags/05_query_with_dates.py
[2023-12-31T12:12:35.834-0300] {processor.py:830} INFO - Processing file /home/felipe/airflow/dags/05_query_with_dates.py for tasks to queue
[2023-12-31T12:12:35.854-0300] {logging_mixin.py:188} INFO - [2023-12-31T12:12:35.844-0300] {dagbag.py:538} INFO - Filling up the DagBag from /home/felipe/airflow/dags/05_query_with_dates.py
[2023-12-31T12:12:35.905-0300] {logging_mixin.py:188} INFO - [2023-12-31T12:12:35.894-0300] {dagbag.py:348} ERROR - Failed to import: /home/felipe/airflow/dags/05_query_with_dates.py
Traceback (most recent call last):
  File "/home/felipe/.local/lib/python3.10/site-packages/airflow/models/dagbag.py", line 344, in parse
    loader.exec_module(new_module)
  File "<frozen importlib._bootstrap_external>", line 883, in exec_module
  File "<frozen importlib._bootstrap>", line 241, in _call_with_frames_removed
  File "/home/felipe/airflow/dags/05_query_with_dates.py", line 4, in <module>
    import pandas as pd
ModuleNotFoundError: No module named 'pandas'
[2023-12-31T12:12:35.915-0300] {processor.py:842} WARNING - No viable dags retrieved from /home/felipe/airflow/dags/05_query_with_dates.py
[2023-12-31T12:12:36.235-0300] {processor.py:183} INFO - Processing /home/felipe/airflow/dags/05_query_with_dates.py took 0.461 seconds
[2023-12-31T12:13:38.224-0300] {processor.py:161} INFO - Started process (PID=37355) to work on /home/felipe/airflow/dags/05_query_with_dates.py
[2023-12-31T12:13:38.244-0300] {processor.py:830} INFO - Processing file /home/felipe/airflow/dags/05_query_with_dates.py for tasks to queue
[2023-12-31T12:13:38.264-0300] {logging_mixin.py:188} INFO - [2023-12-31T12:13:38.255-0300] {dagbag.py:538} INFO - Filling up the DagBag from /home/felipe/airflow/dags/05_query_with_dates.py
[2023-12-31T12:13:38.305-0300] {logging_mixin.py:188} INFO - [2023-12-31T12:13:38.294-0300] {dagbag.py:348} ERROR - Failed to import: /home/felipe/airflow/dags/05_query_with_dates.py
Traceback (most recent call last):
  File "/home/felipe/.local/lib/python3.10/site-packages/airflow/models/dagbag.py", line 344, in parse
    loader.exec_module(new_module)
  File "<frozen importlib._bootstrap_external>", line 883, in exec_module
  File "<frozen importlib._bootstrap>", line 241, in _call_with_frames_removed
  File "/home/felipe/airflow/dags/05_query_with_dates.py", line 4, in <module>
    import pandas as pd
ModuleNotFoundError: No module named 'pandas'
[2023-12-31T12:13:38.314-0300] {processor.py:842} WARNING - No viable dags retrieved from /home/felipe/airflow/dags/05_query_with_dates.py
[2023-12-31T12:13:38.724-0300] {processor.py:183} INFO - Processing /home/felipe/airflow/dags/05_query_with_dates.py took 0.560 seconds
[2023-12-31T12:14:47.254-0300] {processor.py:161} INFO - Started process (PID=37469) to work on /home/felipe/airflow/dags/05_query_with_dates.py
[2023-12-31T12:14:47.264-0300] {processor.py:830} INFO - Processing file /home/felipe/airflow/dags/05_query_with_dates.py for tasks to queue
[2023-12-31T12:14:47.284-0300] {logging_mixin.py:188} INFO - [2023-12-31T12:14:47.274-0300] {dagbag.py:538} INFO - Filling up the DagBag from /home/felipe/airflow/dags/05_query_with_dates.py
[2023-12-31T12:14:47.335-0300] {logging_mixin.py:188} INFO - [2023-12-31T12:14:47.324-0300] {dagbag.py:348} ERROR - Failed to import: /home/felipe/airflow/dags/05_query_with_dates.py
Traceback (most recent call last):
  File "/home/felipe/.local/lib/python3.10/site-packages/airflow/models/dagbag.py", line 344, in parse
    loader.exec_module(new_module)
  File "<frozen importlib._bootstrap_external>", line 883, in exec_module
  File "<frozen importlib._bootstrap>", line 241, in _call_with_frames_removed
  File "/home/felipe/airflow/dags/05_query_with_dates.py", line 4, in <module>
    import pandas as pd
ModuleNotFoundError: No module named 'pandas'
[2023-12-31T12:14:47.345-0300] {processor.py:842} WARNING - No viable dags retrieved from /home/felipe/airflow/dags/05_query_with_dates.py
[2023-12-31T12:14:47.674-0300] {processor.py:183} INFO - Processing /home/felipe/airflow/dags/05_query_with_dates.py took 0.460 seconds
[2023-12-31T12:15:42.004-0300] {processor.py:161} INFO - Started process (PID=37540) to work on /home/felipe/airflow/dags/05_query_with_dates.py
[2023-12-31T12:15:42.034-0300] {processor.py:830} INFO - Processing file /home/felipe/airflow/dags/05_query_with_dates.py for tasks to queue
[2023-12-31T12:15:42.065-0300] {logging_mixin.py:188} INFO - [2023-12-31T12:15:42.064-0300] {dagbag.py:538} INFO - Filling up the DagBag from /home/felipe/airflow/dags/05_query_with_dates.py
[2023-12-31T12:15:42.175-0300] {logging_mixin.py:188} INFO - [2023-12-31T12:15:42.154-0300] {dagbag.py:348} ERROR - Failed to import: /home/felipe/airflow/dags/05_query_with_dates.py
Traceback (most recent call last):
  File "/home/felipe/.local/lib/python3.10/site-packages/airflow/models/dagbag.py", line 344, in parse
    loader.exec_module(new_module)
  File "<frozen importlib._bootstrap_external>", line 883, in exec_module
  File "<frozen importlib._bootstrap>", line 241, in _call_with_frames_removed
  File "/home/felipe/airflow/dags/05_query_with_dates.py", line 4, in <module>
    import pandas as pd
ModuleNotFoundError: No module named 'pandas'
[2023-12-31T12:15:42.185-0300] {processor.py:842} WARNING - No viable dags retrieved from /home/felipe/airflow/dags/05_query_with_dates.py
[2023-12-31T12:15:42.724-0300] {processor.py:183} INFO - Processing /home/felipe/airflow/dags/05_query_with_dates.py took 0.770 seconds
[2023-12-31T12:16:50.495-0300] {processor.py:161} INFO - Started process (PID=37629) to work on /home/felipe/airflow/dags/05_query_with_dates.py
[2023-12-31T12:16:50.514-0300] {processor.py:830} INFO - Processing file /home/felipe/airflow/dags/05_query_with_dates.py for tasks to queue
[2023-12-31T12:16:50.534-0300] {logging_mixin.py:188} INFO - [2023-12-31T12:16:50.524-0300] {dagbag.py:538} INFO - Filling up the DagBag from /home/felipe/airflow/dags/05_query_with_dates.py
[2023-12-31T12:16:50.585-0300] {logging_mixin.py:188} INFO - [2023-12-31T12:16:50.574-0300] {dagbag.py:348} ERROR - Failed to import: /home/felipe/airflow/dags/05_query_with_dates.py
Traceback (most recent call last):
  File "/home/felipe/.local/lib/python3.10/site-packages/airflow/models/dagbag.py", line 344, in parse
    loader.exec_module(new_module)
  File "<frozen importlib._bootstrap_external>", line 883, in exec_module
  File "<frozen importlib._bootstrap>", line 241, in _call_with_frames_removed
  File "/home/felipe/airflow/dags/05_query_with_dates.py", line 4, in <module>
    import pandas as pd
ModuleNotFoundError: No module named 'pandas'
[2023-12-31T12:16:50.594-0300] {processor.py:842} WARNING - No viable dags retrieved from /home/felipe/airflow/dags/05_query_with_dates.py
[2023-12-31T12:16:50.904-0300] {processor.py:183} INFO - Processing /home/felipe/airflow/dags/05_query_with_dates.py took 0.460 seconds
[2023-12-31T12:18:05.014-0300] {processor.py:161} INFO - Started process (PID=37724) to work on /home/felipe/airflow/dags/05_query_with_dates.py
[2023-12-31T12:18:05.034-0300] {processor.py:830} INFO - Processing file /home/felipe/airflow/dags/05_query_with_dates.py for tasks to queue
[2023-12-31T12:18:05.045-0300] {logging_mixin.py:188} INFO - [2023-12-31T12:18:05.044-0300] {dagbag.py:538} INFO - Filling up the DagBag from /home/felipe/airflow/dags/05_query_with_dates.py
[2023-12-31T12:18:05.114-0300] {logging_mixin.py:188} INFO - [2023-12-31T12:18:05.094-0300] {dagbag.py:348} ERROR - Failed to import: /home/felipe/airflow/dags/05_query_with_dates.py
Traceback (most recent call last):
  File "/home/felipe/.local/lib/python3.10/site-packages/airflow/models/dagbag.py", line 344, in parse
    loader.exec_module(new_module)
  File "<frozen importlib._bootstrap_external>", line 883, in exec_module
  File "<frozen importlib._bootstrap>", line 241, in _call_with_frames_removed
  File "/home/felipe/airflow/dags/05_query_with_dates.py", line 4, in <module>
    import pandas as pd
ModuleNotFoundError: No module named 'pandas'
[2023-12-31T12:18:05.115-0300] {processor.py:842} WARNING - No viable dags retrieved from /home/felipe/airflow/dags/05_query_with_dates.py
[2023-12-31T12:18:05.545-0300] {processor.py:183} INFO - Processing /home/felipe/airflow/dags/05_query_with_dates.py took 0.561 seconds
[2023-12-31T12:19:01.044-0300] {processor.py:161} INFO - Started process (PID=37798) to work on /home/felipe/airflow/dags/05_query_with_dates.py
[2023-12-31T12:19:01.074-0300] {processor.py:830} INFO - Processing file /home/felipe/airflow/dags/05_query_with_dates.py for tasks to queue
[2023-12-31T12:19:01.124-0300] {logging_mixin.py:188} INFO - [2023-12-31T12:19:01.094-0300] {dagbag.py:538} INFO - Filling up the DagBag from /home/felipe/airflow/dags/05_query_with_dates.py
[2023-12-31T12:19:01.334-0300] {logging_mixin.py:188} INFO - [2023-12-31T12:19:01.294-0300] {dagbag.py:348} ERROR - Failed to import: /home/felipe/airflow/dags/05_query_with_dates.py
Traceback (most recent call last):
  File "/home/felipe/.local/lib/python3.10/site-packages/airflow/models/dagbag.py", line 344, in parse
    loader.exec_module(new_module)
  File "<frozen importlib._bootstrap_external>", line 883, in exec_module
  File "<frozen importlib._bootstrap>", line 241, in _call_with_frames_removed
  File "/home/felipe/airflow/dags/05_query_with_dates.py", line 4, in <module>
    import pandas as pd
ModuleNotFoundError: No module named 'pandas'
[2023-12-31T12:19:01.364-0300] {processor.py:842} WARNING - No viable dags retrieved from /home/felipe/airflow/dags/05_query_with_dates.py
[2023-12-31T12:19:02.204-0300] {processor.py:183} INFO - Processing /home/felipe/airflow/dags/05_query_with_dates.py took 1.460 seconds
[2023-12-31T12:26:18.710-0300] {processor.py:161} INFO - Started process (PID=37981) to work on /home/felipe/airflow/dags/05_query_with_dates.py
[2023-12-31T12:26:18.721-0300] {processor.py:830} INFO - Processing file /home/felipe/airflow/dags/05_query_with_dates.py for tasks to queue
[2023-12-31T12:26:18.750-0300] {logging_mixin.py:188} INFO - [2023-12-31T12:26:18.741-0300] {dagbag.py:538} INFO - Filling up the DagBag from /home/felipe/airflow/dags/05_query_with_dates.py
[2023-12-31T12:26:18.821-0300] {logging_mixin.py:188} INFO - [2023-12-31T12:26:18.801-0300] {dagbag.py:348} ERROR - Failed to import: /home/felipe/airflow/dags/05_query_with_dates.py
Traceback (most recent call last):
  File "/home/felipe/.local/lib/python3.10/site-packages/airflow/models/dagbag.py", line 344, in parse
    loader.exec_module(new_module)
  File "<frozen importlib._bootstrap_external>", line 883, in exec_module
  File "<frozen importlib._bootstrap>", line 241, in _call_with_frames_removed
  File "/home/felipe/airflow/dags/05_query_with_dates.py", line 4, in <module>
    import pandas as pd
ModuleNotFoundError: No module named 'pandas'
[2023-12-31T12:26:18.840-0300] {processor.py:842} WARNING - No viable dags retrieved from /home/felipe/airflow/dags/05_query_with_dates.py
[2023-12-31T12:26:19.331-0300] {processor.py:183} INFO - Processing /home/felipe/airflow/dags/05_query_with_dates.py took 0.690 seconds
[2023-12-31T12:27:28.021-0300] {processor.py:161} INFO - Started process (PID=38054) to work on /home/felipe/airflow/dags/05_query_with_dates.py
[2023-12-31T12:27:28.041-0300] {processor.py:830} INFO - Processing file /home/felipe/airflow/dags/05_query_with_dates.py for tasks to queue
[2023-12-31T12:27:28.070-0300] {logging_mixin.py:188} INFO - [2023-12-31T12:27:28.060-0300] {dagbag.py:538} INFO - Filling up the DagBag from /home/felipe/airflow/dags/05_query_with_dates.py
[2023-12-31T12:27:28.141-0300] {logging_mixin.py:188} INFO - [2023-12-31T12:27:28.120-0300] {dagbag.py:348} ERROR - Failed to import: /home/felipe/airflow/dags/05_query_with_dates.py
Traceback (most recent call last):
  File "/home/felipe/.local/lib/python3.10/site-packages/airflow/models/dagbag.py", line 344, in parse
    loader.exec_module(new_module)
  File "<frozen importlib._bootstrap_external>", line 883, in exec_module
  File "<frozen importlib._bootstrap>", line 241, in _call_with_frames_removed
  File "/home/felipe/airflow/dags/05_query_with_dates.py", line 4, in <module>
    import pandas as pd
ModuleNotFoundError: No module named 'pandas'
[2023-12-31T12:27:28.151-0300] {processor.py:842} WARNING - No viable dags retrieved from /home/felipe/airflow/dags/05_query_with_dates.py
[2023-12-31T12:27:28.561-0300] {processor.py:183} INFO - Processing /home/felipe/airflow/dags/05_query_with_dates.py took 0.611 seconds
[2023-12-31T12:28:43.660-0300] {processor.py:161} INFO - Started process (PID=38110) to work on /home/felipe/airflow/dags/05_query_with_dates.py
[2023-12-31T12:28:43.681-0300] {processor.py:830} INFO - Processing file /home/felipe/airflow/dags/05_query_with_dates.py for tasks to queue
[2023-12-31T12:28:43.701-0300] {logging_mixin.py:188} INFO - [2023-12-31T12:28:43.691-0300] {dagbag.py:538} INFO - Filling up the DagBag from /home/felipe/airflow/dags/05_query_with_dates.py
[2023-12-31T12:28:43.790-0300] {logging_mixin.py:188} INFO - [2023-12-31T12:28:43.770-0300] {dagbag.py:348} ERROR - Failed to import: /home/felipe/airflow/dags/05_query_with_dates.py
Traceback (most recent call last):
  File "/home/felipe/.local/lib/python3.10/site-packages/airflow/models/dagbag.py", line 344, in parse
    loader.exec_module(new_module)
  File "<frozen importlib._bootstrap_external>", line 883, in exec_module
  File "<frozen importlib._bootstrap>", line 241, in _call_with_frames_removed
  File "/home/felipe/airflow/dags/05_query_with_dates.py", line 4, in <module>
    import pandas as pd
ModuleNotFoundError: No module named 'pandas'
[2023-12-31T12:28:43.801-0300] {processor.py:842} WARNING - No viable dags retrieved from /home/felipe/airflow/dags/05_query_with_dates.py
[2023-12-31T12:28:44.261-0300] {processor.py:183} INFO - Processing /home/felipe/airflow/dags/05_query_with_dates.py took 0.650 seconds
[2023-12-31T12:29:56.900-0300] {processor.py:161} INFO - Started process (PID=38167) to work on /home/felipe/airflow/dags/05_query_with_dates.py
[2023-12-31T12:29:56.921-0300] {processor.py:830} INFO - Processing file /home/felipe/airflow/dags/05_query_with_dates.py for tasks to queue
[2023-12-31T12:29:56.941-0300] {logging_mixin.py:188} INFO - [2023-12-31T12:29:56.931-0300] {dagbag.py:538} INFO - Filling up the DagBag from /home/felipe/airflow/dags/05_query_with_dates.py
[2023-12-31T12:29:57.011-0300] {logging_mixin.py:188} INFO - [2023-12-31T12:29:56.991-0300] {dagbag.py:348} ERROR - Failed to import: /home/felipe/airflow/dags/05_query_with_dates.py
Traceback (most recent call last):
  File "/home/felipe/.local/lib/python3.10/site-packages/airflow/models/dagbag.py", line 344, in parse
    loader.exec_module(new_module)
  File "<frozen importlib._bootstrap_external>", line 883, in exec_module
  File "<frozen importlib._bootstrap>", line 241, in _call_with_frames_removed
  File "/home/felipe/airflow/dags/05_query_with_dates.py", line 4, in <module>
    import pandas as pd
ModuleNotFoundError: No module named 'pandas'
[2023-12-31T12:29:57.030-0300] {processor.py:842} WARNING - No viable dags retrieved from /home/felipe/airflow/dags/05_query_with_dates.py
[2023-12-31T12:29:57.520-0300] {processor.py:183} INFO - Processing /home/felipe/airflow/dags/05_query_with_dates.py took 0.671 seconds
[2023-12-31T12:31:12.010-0300] {processor.py:161} INFO - Started process (PID=38242) to work on /home/felipe/airflow/dags/05_query_with_dates.py
[2023-12-31T12:31:12.031-0300] {processor.py:830} INFO - Processing file /home/felipe/airflow/dags/05_query_with_dates.py for tasks to queue
[2023-12-31T12:31:12.051-0300] {logging_mixin.py:188} INFO - [2023-12-31T12:31:12.041-0300] {dagbag.py:538} INFO - Filling up the DagBag from /home/felipe/airflow/dags/05_query_with_dates.py
[2023-12-31T12:31:12.131-0300] {logging_mixin.py:188} INFO - [2023-12-31T12:31:12.111-0300] {dagbag.py:348} ERROR - Failed to import: /home/felipe/airflow/dags/05_query_with_dates.py
Traceback (most recent call last):
  File "/home/felipe/.local/lib/python3.10/site-packages/airflow/models/dagbag.py", line 344, in parse
    loader.exec_module(new_module)
  File "<frozen importlib._bootstrap_external>", line 883, in exec_module
  File "<frozen importlib._bootstrap>", line 241, in _call_with_frames_removed
  File "/home/felipe/airflow/dags/05_query_with_dates.py", line 4, in <module>
    import pandas as pd
ModuleNotFoundError: No module named 'pandas'
[2023-12-31T12:31:12.150-0300] {processor.py:842} WARNING - No viable dags retrieved from /home/felipe/airflow/dags/05_query_with_dates.py
[2023-12-31T12:31:12.631-0300] {processor.py:183} INFO - Processing /home/felipe/airflow/dags/05_query_with_dates.py took 0.680 seconds
[2023-12-31T12:32:33.131-0300] {processor.py:161} INFO - Started process (PID=38296) to work on /home/felipe/airflow/dags/05_query_with_dates.py
[2023-12-31T12:32:33.161-0300] {processor.py:830} INFO - Processing file /home/felipe/airflow/dags/05_query_with_dates.py for tasks to queue
[2023-12-31T12:32:33.190-0300] {logging_mixin.py:188} INFO - [2023-12-31T12:32:33.180-0300] {dagbag.py:538} INFO - Filling up the DagBag from /home/felipe/airflow/dags/05_query_with_dates.py
[2023-12-31T12:32:33.270-0300] {logging_mixin.py:188} INFO - [2023-12-31T12:32:33.240-0300] {dagbag.py:348} ERROR - Failed to import: /home/felipe/airflow/dags/05_query_with_dates.py
Traceback (most recent call last):
  File "/home/felipe/.local/lib/python3.10/site-packages/airflow/models/dagbag.py", line 344, in parse
    loader.exec_module(new_module)
  File "<frozen importlib._bootstrap_external>", line 883, in exec_module
  File "<frozen importlib._bootstrap>", line 241, in _call_with_frames_removed
  File "/home/felipe/airflow/dags/05_query_with_dates.py", line 4, in <module>
    import pandas as pd
ModuleNotFoundError: No module named 'pandas'
[2023-12-31T12:32:33.281-0300] {processor.py:842} WARNING - No viable dags retrieved from /home/felipe/airflow/dags/05_query_with_dates.py
[2023-12-31T12:32:33.771-0300] {processor.py:183} INFO - Processing /home/felipe/airflow/dags/05_query_with_dates.py took 0.710 seconds
[2023-12-31T12:34:04.480-0300] {processor.py:161} INFO - Started process (PID=38351) to work on /home/felipe/airflow/dags/05_query_with_dates.py
[2023-12-31T12:34:04.501-0300] {processor.py:830} INFO - Processing file /home/felipe/airflow/dags/05_query_with_dates.py for tasks to queue
[2023-12-31T12:34:04.531-0300] {logging_mixin.py:188} INFO - [2023-12-31T12:34:04.521-0300] {dagbag.py:538} INFO - Filling up the DagBag from /home/felipe/airflow/dags/05_query_with_dates.py
[2023-12-31T12:34:04.660-0300] {logging_mixin.py:188} INFO - [2023-12-31T12:34:04.630-0300] {dagbag.py:348} ERROR - Failed to import: /home/felipe/airflow/dags/05_query_with_dates.py
Traceback (most recent call last):
  File "/home/felipe/.local/lib/python3.10/site-packages/airflow/models/dagbag.py", line 344, in parse
    loader.exec_module(new_module)
  File "<frozen importlib._bootstrap_external>", line 883, in exec_module
  File "<frozen importlib._bootstrap>", line 241, in _call_with_frames_removed
  File "/home/felipe/airflow/dags/05_query_with_dates.py", line 4, in <module>
    import pandas as pd
ModuleNotFoundError: No module named 'pandas'
[2023-12-31T12:34:04.680-0300] {processor.py:842} WARNING - No viable dags retrieved from /home/felipe/airflow/dags/05_query_with_dates.py
[2023-12-31T12:34:05.180-0300] {processor.py:183} INFO - Processing /home/felipe/airflow/dags/05_query_with_dates.py took 0.790 seconds
[2023-12-31T12:35:43.181-0300] {processor.py:161} INFO - Started process (PID=38436) to work on /home/felipe/airflow/dags/05_query_with_dates.py
[2023-12-31T12:35:43.220-0300] {processor.py:830} INFO - Processing file /home/felipe/airflow/dags/05_query_with_dates.py for tasks to queue
[2023-12-31T12:35:43.261-0300] {logging_mixin.py:188} INFO - [2023-12-31T12:35:43.241-0300] {dagbag.py:538} INFO - Filling up the DagBag from /home/felipe/airflow/dags/05_query_with_dates.py
[2023-12-31T12:35:43.490-0300] {logging_mixin.py:188} INFO - [2023-12-31T12:35:43.440-0300] {dagbag.py:348} ERROR - Failed to import: /home/felipe/airflow/dags/05_query_with_dates.py
Traceback (most recent call last):
  File "/home/felipe/.local/lib/python3.10/site-packages/airflow/models/dagbag.py", line 344, in parse
    loader.exec_module(new_module)
  File "<frozen importlib._bootstrap_external>", line 883, in exec_module
  File "<frozen importlib._bootstrap>", line 241, in _call_with_frames_removed
  File "/home/felipe/airflow/dags/05_query_with_dates.py", line 4, in <module>
    import pandas as pd
ModuleNotFoundError: No module named 'pandas'
[2023-12-31T12:35:43.511-0300] {processor.py:842} WARNING - No viable dags retrieved from /home/felipe/airflow/dags/05_query_with_dates.py
[2023-12-31T12:35:44.160-0300] {processor.py:183} INFO - Processing /home/felipe/airflow/dags/05_query_with_dates.py took 1.120 seconds
[2023-12-31T12:37:50.670-0300] {processor.py:161} INFO - Started process (PID=38507) to work on /home/felipe/airflow/dags/05_query_with_dates.py
[2023-12-31T12:37:50.710-0300] {processor.py:830} INFO - Processing file /home/felipe/airflow/dags/05_query_with_dates.py for tasks to queue
[2023-12-31T12:37:50.810-0300] {logging_mixin.py:188} INFO - [2023-12-31T12:37:50.770-0300] {dagbag.py:538} INFO - Filling up the DagBag from /home/felipe/airflow/dags/05_query_with_dates.py
[2023-12-31T12:37:51.030-0300] {logging_mixin.py:188} INFO - [2023-12-31T12:37:50.951-0300] {dagbag.py:348} ERROR - Failed to import: /home/felipe/airflow/dags/05_query_with_dates.py
Traceback (most recent call last):
  File "/home/felipe/.local/lib/python3.10/site-packages/airflow/models/dagbag.py", line 344, in parse
    loader.exec_module(new_module)
  File "<frozen importlib._bootstrap_external>", line 883, in exec_module
  File "<frozen importlib._bootstrap>", line 241, in _call_with_frames_removed
  File "/home/felipe/airflow/dags/05_query_with_dates.py", line 4, in <module>
    import pandas as pd
ModuleNotFoundError: No module named 'pandas'
[2023-12-31T12:37:51.060-0300] {processor.py:842} WARNING - No viable dags retrieved from /home/felipe/airflow/dags/05_query_with_dates.py
[2023-12-31T12:37:52.011-0300] {processor.py:183} INFO - Processing /home/felipe/airflow/dags/05_query_with_dates.py took 1.480 seconds
[2023-12-31T12:49:13.888-0300] {processor.py:161} INFO - Started process (PID=38819) to work on /home/felipe/airflow/dags/05_query_with_dates.py
[2023-12-31T12:49:13.968-0300] {processor.py:830} INFO - Processing file /home/felipe/airflow/dags/05_query_with_dates.py for tasks to queue
[2023-12-31T12:49:14.068-0300] {logging_mixin.py:188} INFO - [2023-12-31T12:49:14.028-0300] {dagbag.py:538} INFO - Filling up the DagBag from /home/felipe/airflow/dags/05_query_with_dates.py
[2023-12-31T12:49:14.437-0300] {logging_mixin.py:188} INFO - [2023-12-31T12:49:14.338-0300] {dagbag.py:348} ERROR - Failed to import: /home/felipe/airflow/dags/05_query_with_dates.py
Traceback (most recent call last):
  File "/home/felipe/.local/lib/python3.10/site-packages/airflow/models/dagbag.py", line 344, in parse
    loader.exec_module(new_module)
  File "<frozen importlib._bootstrap_external>", line 883, in exec_module
  File "<frozen importlib._bootstrap>", line 241, in _call_with_frames_removed
  File "/home/felipe/airflow/dags/05_query_with_dates.py", line 4, in <module>
    import pandas as pd
ModuleNotFoundError: No module named 'pandas'
[2023-12-31T12:49:14.468-0300] {processor.py:842} WARNING - No viable dags retrieved from /home/felipe/airflow/dags/05_query_with_dates.py
[2023-12-31T12:49:16.057-0300] {processor.py:183} INFO - Processing /home/felipe/airflow/dags/05_query_with_dates.py took 2.450 seconds
